Workbook
Name A458DC1025: DESCUENTOS!$B$220:$D$246
Name ARRCART4: carteras!$AQ$505:$AS$606
Name ARRIOALIM: ARRIOLA!$CV$312:$DK$455
Name ARRIOFC: ARRIOLA!$CV$165:$DK$309
Name ARRIOLA24: '2024'!$A$761:$N$902
Name ARRIOLACARTERA: carteras!$AQ$1:$AS$140
Name ARRIOLCART2: carteras!$AQ$172:$AS$304
Name ARRIOLFIN: ARRIOLA!$A$2:$M$149
Name BAS_UC: BASILE!$CO$154:$CP$283
Name BASALIM: BASILE!$CT$330:$DI$470
Name BASCART3: carteras!$G$338:$I$495
Name BASCART4: carteras!$G$505:$I$668
Name BASFC: BASILE!$CT$181:$DI$325
Name BASILECART2: carteras!$G$172:$J$324
Name BASILECARTERA: carteras!$G$1:$I$148
Name Basilee24: '2024'!$A$2:$N$133
Name bassfin: BASILE!$A$2:$M$165
Name BUEALIM: BUELA!$CV$319:$DK$462
Name BUECART4: carteras!$A$505:$C$641
Name BUEFC: BUELA!$CV$172:$DK$316
Name BUELA: '2024'!$A$503:$N$624
Name BUELACART2: carteras!$A$172:$C$314
Name BUELACARTERA: carteras!$A$1:$C$130
Name buelafin: BUELA!$A$2:$M$136
Name CALO24: '2024'!$A$138:$N$241
Name CALOALIM: CALO!$CU$303:$DJ$446
Name calocart2: carteras!$R$173:$U$281
Name CALOCART4: carteras!$R$506:$T$610
Name CALOCARTERA: carteras!$R$2:$T$117
Name CALOFC: CALO!$CU$156:$DJ$300
Name calofin: CALO!$A$2:$I$113
Name CART.ARR.3: carteras!$AQ$337:$AT$463
Name CART.BAS.3: carteras!$G$337:$J$503
Name CART.BUE.3: carteras!$A$337:$D$478
Name CART.CAL.3: carteras!$R$337:$U$442
Name CART.LAG.3: carteras!$M$338:$P$514
Name CART.LAV.3: carteras!$AW$337:$AY$456
Name CART.MAR.3: carteras!$AL$338:$AN$466
Name CART.MON.3: carteras!$AG$338:$AJ$471
Name cart.ret.3: carteras!$W$337:$Z$452
Name CART.VAR.3: carteras!$AB$338:$AE$453
Name CARTEROTEPECH: 'Hoja 23'!$C$81:$D$197
Name CARTLES1: carteras!$BL$506:$BN$596
Name DES: DESCUENTOS!$B$76:$E$116
Name LAGALIM: LAGE!$CZ$340:$DO$483
Name LAGE24: '2024'!$A$355:$N$499
Name LAGECART2: carteras!$M$172:$P$344
Name LAGECART4: carteras!$M$505:$P$664
Name LAGECARTERA: carteras!$M$1:$O$193
Name LAGEFC: LAGE!$CZ$196:$DO$337
Name LAGEFIN: LAGE!$A$2:$M$180
Name lavcart4: carteras!$AW$506:$AY$633
Name LAVEFC: LAVENIA!$CU$187:$DJ$331
Name LAVENIACART2: carteras!$AW$173:$AY$297
Name LAVENIACARTERA: carteras!$AW$1:$AY$124
Name LAVENIAFIN: LAVENIA!$A$2:$M$202
Name MAICART1: carteras!$BG$506:$BI$606
Name MARCART4: carteras!$AL$506:$AO$572
Name MARUCA24: '2024'!$A$907:$N$1031
Name MARUCAALIM: MARUCA!$CV$354:$DK$496

Sheet 2025
B4: EJECUTIVO | C4: % DESCUENTO FARMACIA | I4: TOTAL CLIENTES
C5: 20/18 | D5: 0.15 | E5: 0.12 | F5: 0.1 | G5: 0.05 | H5: SIN
B6: JUAN PABLO BASILE | C6: =BASILE!CJ2 -> 0 | D6: =BASILE!CJ3 -> 11 | E6: =BASILE!CJ4 -> 0 | F6: =BASILE!CJ5 -> 24 | G6: =BASILE!CJ6 -> 0 | H6: =BASILE!CJ7 -> 114 | I6: =SUM(C6:H6) -> 149
B7: MARIO CALO | C7: =CALO!CB2 -> 0 | D7: =CALO!CB3 -> 9 | E7: =CALO!CB4 -> 0 | F7: =CALO!CB5 -> 18 | G7: =CALO!CB6 -> 8 | H7: =CALO!CB7 -> 63 | I7: =SUM(C7:H7) -> 98
B8: MATIAS RETAMAR | C8: =RETAMAR!CC2 -> 0 | D8: =RETAMAR!CC3 -> 8 | E8: =RETAMAR!CC4 -> 2 | F8: =RETAMAR!CC5 -> 45 | G8: =RETAMAR!CC6 -> 7 | H8: =RETAMAR!CC7 -> 33 | I8: =SUM(C8:H8) -> 95
B9: LAGE FEDERICO | C9: =LAGE!CJ2 -> 0 | D9: =LAGE!CJ3 -> 10 | E9: =LAGE!CJ4 -> 0 | F9: =LAGE!CJ5 -> 31 | G9: =LAGE!CJ6 -> 1 | H9: =LAGE!CJ7 -> 117 | I9: =SUM(C9:H9) -> 159
B10: BUELA EZEQUIEL | C10: =BUELA!CF2 -> 1 | D10: =BUELA!CF3 -> 9 | E10: =BUELA!CF4 -> 5 | F10: =BUELA!CF5 -> 16 | G10: =BUELA!CF6 -> 1 | H10: =BUELA!CF7 -> 96 | I10: =SUM(C10:H10) -> 128
B11: VARGAS JORGE | D11: =VARGAS!CG3 -> 6 | E11: =VARGAS!CG4 -> 0 | F11: =VARGAS!CG5 -> 31 | G11: =VARGAS!CG6 -> 0 | H11: =VARGAS!CG7 -> 26 | I11: =SUM(C11:H11) -> 63
B12: ROLANDO ARRIOLA | D12: =ARRIOLA!CF3 -> 7 | E12: =ARRIOLA!CF4 -> 0 | F12: =ARRIOLA!CF5 -> 31 | G12: =ARRIOLA!CF6 -> 0 | H12: =ARRIOLA!CF7 -> 58 | I12: =SUM(C12:H12) -> 96
B13: MONTENEGRO MATIAS | D13: =MONTENEGRO!CB3 -> 10 | E13: =MONTENEGRO!CB4 -> 1 | F13: =MONTENEGRO!CB5 -> 56 | G13: =MONTENEGRO!CB6 -> 0 | H13: =MONTENEGRO!CB7 -> 55 | I13: =SUM(C13:H13) -> 122
B14: MARUCA EZEQUIEL | D14: =MARUCA!CF3 -> 4 | E14: =MARUCA!CF4 -> 0 | F14: =MARUCA!CF5 -> 20 | G14: =MARUCA!CF6 -> 3 | H14: =MARUCA!CF7 -> 30 | I14: =SUM(C14:H14) -> 57
B15: MARIANA /AYELEN | D15: =PEREZ!AN3 -> 0 | E15: =PEREZ!AN4 -> 0 | F15: =PEREZ!AN5 -> 0 | G15: =PEREZ!AN6 -> 0 | H15: 32 | I15: =SUM(C15:H15) -> 32
B16: ROTELA LEANDRO | D16: =ROTELA!AV3 -> 0 | E16: =ROTELA!AV4 -> 0 | F16: =ROTELA!AV5 -> 0 | G16: =ROTELA!AV6 -> 0 | H16: =ROTELA!AV7 -> 0 | I16: =SUM(C16:H16) -> 0
B17: LAVENIA VANESA | D17: =LAVENIA!CF3 -> 10 | E17: =LAVENIA!CF4 -> 1 | F17: =LAVENIA!CF5 -> 65 | G17: =LAVENIA!CF6 -> 3 | H17: =LAVENIA!CF7 -> 36 | I17: =SUM(C17:H17) -> 115
B18: TOTAL: | C18: =SUM(C6:C17) -> 1 | D18: =SUM(D6:D17) -> 84 | E18: =SUM(E6:E17) -> 9 | F18: =SUM(F6:F17) -> 337 | G18: =SUM(G6:G17) -> 23 | H18: =SUM(H6:H17) -> 660 | I18: =SUM(C18:H18) -> 1114
B22: Al 11 AGOSTO
B23: EJECUTIVO | C23: % DESCUENTO FARMACIA | I23: TOTAL CLIENTES
C24: 0.2 | D24: 0.15 | E24: 0.12 | F24: 0.1 | G24: 0.05 | H24: SIN
B25: JUAN PABLO BASILE | D25: 11 | E25: 1 | F25: 34 | G25: 3 | H25: 95 | I25: 144
B26: MARIO CALO | D26: 9 | F26: 18 | G26: 8 | H26: 65 | I26: 100
B27: MATIAS RETAMAR | D27: 10 | E27: 2 | F27: 48 | G27: 8 | H27: 34 | I27: 102
B28: LAGE FEDERICO | D28: 12 | E28: 0 | F28: 96 | G28: 3 | H28: 35 | I28: 146
B29: BUELA EZEQUIEL | C29: 1 | D29: 8 | E29: 5 | F29: 38 | G29: 2 | H29: 65 | I29: 119
B30: VARGAS JORGE | D30: 4 | E30: 2 | F30: 44 | G30: 8 | H30: 48 | I30: 106
B31: ROLANDO ARRIOLA | D31: 18 | F31: 61 | G31: 10 | H31: 35 | I31: 124
B32: MONTENEGRO MATIAS | D32: 21 | F32: 59 | G32: 8 | H32: 40 | I32: 128
B33: MARUCA EZEQUIEL | D33: 2 | F33: 27 | G33: 18 | H33: 70 | I33: 117
B34: MARIANA /AYELEN | H34: 33 | I34: 33
B35: ROTELA LEANDRO | I35: 0
B36: LAVENIA VANESA | D36: 9 | E36: 3 | F36: 69 | G36: 2 | H36: 34 | I36: 117
B37: TOTAL: | C37: 1 | D37: 104 | E37: 13 | F37: 494 | G37: 70 | H37: 554 | I37: 1236

Sheet BASILE
A1: COD | B1: ID | C1: FAR | D1: ALI | E1: COR | F1: ID | G1: FAR | H1: ALI | I1: COR | J1: ID | K1: FAR | L1: ALI | M1: RAZON SOCIAL | N1: 45681 | O1: OBJ. ENE | P1: FARM | Q1: ALIM | R1: FC. ENERO | S1: FALTA/ SUPERÓ | T1: % | U1: 45712 | V1: OBJ. FEB | W1: FARM | X1: ALIM | Y1: FC. FEBRERO | Z1: FALTA/ SUPERÓ | AA1: % | AB1: 45740 | AC1: OBJ. MAR | AD1: FARM | AE1: ALIM | AF1: FC. MARZO | AG1: FALTA/ SUPERÓ | AH1: % | AI1: OBJ TRIMESTRE | AJ1: FC OCT-DIC 2024 | AK1: ALIM | AL1: FARM | AM1: FC TRIMESTRE | AN1: FALTA/ SUPERÓ | AO1: % | AP1: 45771 | AQ1: FARM | AR1: ALIM | AS1: FC. ABRIL | AT1: 45801 | AU1: FARM | AV1: ALIM | AW1: FC. MAYO | AX1: 45832 | AY1: FARM | AZ1: ALIM | BA1: FC. JUNIO | BB1: FARM | BC1: ALIM | BD1: FC. TRIMESTRE | BE1: FARM | BF1: ALIM | BG1: FC. 1ER- SEMESTRE | BH1: FARM | BI1: ALIM | BJ1: FC. JULIO | BK1: 45893 | BL1: FARM | BM1: ALIM | BN1: FC. AGOSTO | BO1: 45924 | BP1: FARM | BQ1: ALIM | BR1: FC. SEPT. | BS1: FARM. TRIM. | BT1: ALIM | BU1: FC. TRIM. | BV1: 45954 | BW1: FARM | BX1: ALIM | BY1: FC. OCTUBRE | BZ1: 45985 | CA1: FARM | CB1: ALIM | CC1: FC. NOVIEMBRE | CD1: 46015 | CI1: DSCTO. FARMACIA | CJ1: ACTUAL | CK1: AL 31/01 | CL1: FEB | CM1: AL 21/03 | CN1: AL 23/04 | CO1: al 20/5 | CP1: al 24/06 | CQ1: AL 15/07 | CR1: Al 30/07 | CS1: 45844 | CT1: AL 15/08 | CU1: al 07/10 | CV1: al 27/10 | CW1: Al 13/11
A2: =VLOOKUP(M2,BASCART4,3,FALSE) -> 112014519 | B2: =VLOOKUP(M2,BASILECARTERA,2,FALSE) -> 10 | C2: =IFERROR(VLOOKUP(B2,DES,2,FALSE),"") -> 0.15 | D2: =IFERROR(VLOOKUP(B2,DES,3,FALSE),"") -> 0.23 | E2: =IFERROR(VLOOKUP(B2,DES,4,FALSE),"") -> 0 | F2: =VLOOKUP(M2,BASILECART2,2,FALSE) -> 38 | G2: =IFERROR(VLOOKUP(F2,DES,2,FALSE),"") -> 0.15 | H2: =IFERROR(VLOOKUP(F2,DES,3,FALSE),"") -> 0.26 | I2: =IFERROR(VLOOKUP(F2,DES,4,FALSE),"") -> 0 | J2: =VLOOKUP(M2,BASCART4,2,FALSE) -> 52 | K2: =IFERROR(VLOOKUP(J2,A458DC1025,2,FALSE),"") -> 0.15 | L2: =IFERROR(VLOOKUP(J2,A458DC1025,3,FALSE),"") -> 0.17 | M2: STRANGIS ADRIAN | N2: =IFERROR(VLOOKUP(M2,Basilee24,3,FALSE),"") -> 0 | O2: 3000000 | P2: =R2-Q2 -> 2219600.3 | Q2: =IFERROR(VLOOKUP(M2,BASALIM,3,FALSE),"") -> 532717.96 | R2: =IFERROR(VLOOKUP(M2,BASFC,3,FALSE),"") -> 2752318.3 | S2: =R2-O2 -> -247681.74 | T2: =R2/O2 -> 0.91743942 | U2: =IFERROR(VLOOKUP(M2,Basilee24,4,FALSE),"") -> 0 | V2: 3000000 | W2: =Y2-X2 -> 3790323.2 | X2: =IFERROR(VLOOKUP(M2,BASALIM,4,FALSE),"") -> 722136.8 | Y2: =IFERROR(VLOOKUP(M2,BASFC,4,FALSE),"") -> 4512460 | Z2: =Y2-V2 -> 1512460 | AA2: =Y2/V2 -> 1.5041533 | AB2: =IFERROR(VLOOKUP(M2,Basilee24,5,FALSE),"") -> 0 | AC2: 3000000 | AD2: =AF2-AE2 -> 714812.54 | AE2: =IFERROR(VLOOKUP(M2,BASALIM,5,FALSE),"") -> 730073.96 | AF2: =IFERROR(VLOOKUP(M2,BASFC,5,FALSE),"") -> 1444886.5 | AG2: =AF2-AC2 -> -1555113.5 | AH2: =AF2/AC2 -> 0.48162883 | AI2: =SUM(O2,V2,AC2) -> 9000000 | AJ2: =IFERROR(VLOOKUP(M2,trim2024,2,FALSE),"0") -> 9461313 | AK2: =SUM(AE2,X2,Q2) -> 1984928.7 | AL2: =SUM(P2,W2,AD2) -> 6724736 | AM2: =AF2+Y2+R2 -> 8709664.8 | AN2: =AM2-AJ2 -> -751648.26 | AO2: =AM2/AJ2 -> 0.92055561 | AP2: =IFERROR(VLOOKUP(M2,Basilee24,6,FALSE),"") -> 0 | AQ2: =AS2-AR2 -> 1491934.2 | AR2: =IFERROR(VLOOKUP(M2,BASALIM,6,FALSE),"") -> 1381583.2 | AS2: =IFERROR(VLOOKUP(M2,BASFC,6,FALSE),"") -> 2873517.4 | AT2: =IFERROR(VLOOKUP(M2,Basilee24,7,FALSE),"") -> 0 | AU2: =AW2-AV2 -> 675247.53 | AV2: =IFERROR(VLOOKUP(M2,BASALIM,7,FALSE),"") -> 338823.72 | AW2: =IFERROR(VLOOKUP(M2,BASFC,7,FALSE),"") -> 1014071.2 | AX2: =IFERROR(VLOOKUP(M2,Basilee24,8,FALSE),"") -> 0 | AY2: =BA2-AZ2 -> 1278327.2 | AZ2: =IFERROR(VLOOKUP(M2,BASALIM,8,FALSE),"") -> 279518.4 | BA2: =IFERROR(VLOOKUP(M2,BASFC,8,FALSE),"") -> 1557845.6 | BB2: =BH2+AY2+AU2 -> 4160739.5 | BC2: =BI2+AZ2+AV2 -> 1839374.2 | BD2: =BJ2+BA2+AW2 -> 6000113.8 | BE2: =BB2+AL2 -> 10885476 | BF2: =BC2+AK2 -> 3824303 | BG2: =SUM(BD2+AM2) -> 14709779 | BH2: =BJ2-BI2 -> 2207164.8 | BI2: =IFERROR(VLOOKUP(M2,BASALIM,9,FALSE),"") -> 1221032.1 | BJ2: =IFERROR(VLOOKUP(M2,BASFC,9,FALSE),"") -> 3428197 | BK2: =IFERROR(VLOOKUP(M2,Basilee24,10,FALSE),"") -> 1264274.6 | BL2: =BN2-BM2 -> 0 | BM2: =IFERROR(VLOOKUP(M2,BASALIM,10,FALSE),"") -> 0 | BN2: =IFERROR(VLOOKUP(M2,BASFC,10,FALSE),"") -> 0 | BO2: =IFERROR(VLOOKUP(M2,Basilee24,11,FALSE),"") -> 2039369.1 | BP2: =BR2-BQ2 -> 1999722.8 | BQ2: =IFERROR(VLOOKUP(M2,BASALIM,11,FALSE),"") -> 945500.15 | BR2: =IFERROR(VLOOKUP(M2,BASFC,11,FALSE),"") -> 2945222.9 | BS2: =BH2+BL2+BP2 -> 4206887.6 | BT2: =SUM(BI2,BM2,BQ2) -> 2166532.3 | BU2: =SUM(BJ2,BN2,BR2) -> 6373419.8 | BV2: =IFERROR(VLOOKUP(M2,Basilee24,12,FALSE),"") -> 2248182.6 | BW2: =BY2-BX2 -> 10547076 | BX2: =IFERROR(VLOOKUP(M2,BASALIM,12,FALSE),"") -> 2532631.5 | BY2: =IFERROR(VLOOKUP(M2,BASFC,12,FALSE),"") -> 13079707 | BZ2: =IFERROR(VLOOKUP(M2,Basilee24,13,FALSE),"") -> 2973025.5 | CD2: =IFERROR(VLOOKUP(M2,Basilee24,14,FALSE),"") -> 4240104.9 | CI2: 0.18 | CV2: 1
A3: =VLOOKUP(M3,BASCART4,3,FALSE) -> 112010681 | B3: =VLOOKUP(M3,BASILECARTERA,2,FALSE) -> 11 | C3: =IFERROR(VLOOKUP(B3,DES,2,FALSE),"") -> 0.15 | D3: =IFERROR(VLOOKUP(B3,DES,3,FALSE),"") -> 0.2 | E3: =IFERROR(VLOOKUP(B3,DES,4,FALSE),"") -> 0 | F3: =VLOOKUP(M3,BASILECART2,2,FALSE) -> 11 | G3: =IFERROR(VLOOKUP(F3,DES,2,FALSE),"") -> 0.15 | H3: =IFERROR(VLOOKUP(F3,DES,3,FALSE),"") -> 0.2 | I3: =IFERROR(VLOOKUP(F3,DES,4,FALSE),"") -> 0 | J3: =VLOOKUP(M3,BASCART4,2,FALSE) -> 54 | K3: =IFERROR(VLOOKUP(J3,A458DC1025,2,FALSE),"") -> 0.15 | L3: =IFERROR(VLOOKUP(J3,A458DC1025,3,FALSE),"") -> 0.11 | M3: ROMANO OSVALDO RUBEN | N3: =IFERROR(VLOOKUP(M3,Basilee24,3,FALSE),"") -> 1619054.6 | P3: =R3-Q3 -> 0 | Q3: =IFERROR(VLOOKUP(M3,BASALIM,3,FALSE),"") -> 0 | R3: =IFERROR(VLOOKUP(M3,BASFC,3,FALSE),"") -> 0 | S3: =R3-O3 -> 0 | T3: =R3/O3 -> #DIV/0! | U3: =IFERROR(VLOOKUP(M3,Basilee24,4,FALSE),"") -> 499675.99 | W3: =Y3-X3 -> 1487996 | X3: =IFERROR(VLOOKUP(M3,BASALIM,4,FALSE),"") -> 29037.44 | Y3: =IFERROR(VLOOKUP(M3,BASFC,4,FALSE),"") -> 1517033.4 | Z3: =Y3-V3 -> 1517033.4 | AA3: =IFERROR(Y3/V3,"") | AB3: =IFERROR(VLOOKUP(M3,Basilee24,5,FALSE),"") -> 633578.85 | AC3: =(AB3*1.5955)*1.03 -> 1041201.3 | AD3: =AF3-AE3 -> 524453.89 | AE3: =IFERROR(VLOOKUP(M3,BASALIM,5,FALSE),"") -> 0 | AF3: =IFERROR(VLOOKUP(M3,BASFC,5,FALSE),"") -> 524453.89 | AG3: =AF3-AC3 -> -516747.42 | AH3: =AF3/AC3 -> 0.50370076 | AI3: =SUM(O3,V3,AC3) -> 1041201.3 | AJ3: =IFERROR(VLOOKUP(M3,trim2024,2,FALSE),"0") -> 3483125.6 | AK3: =SUM(AE3,X3,Q3) -> 29037.44 | AL3: =SUM(P3,W3,AD3) -> 2012449.9 | AM3: =AF3+Y3+R3 -> 2041487.3 | AN3: =AM3-AJ3 -> -1441638.3 | AO3: =AM3/AJ3 -> 0.58610787 | AP3: =IFERROR(VLOOKUP(M3,Basilee24,6,FALSE),"") -> 1419591.3 | AQ3: =AS3-AR3 -> 2093842.6 | AR3: =IFERROR(VLOOKUP(M3,BASALIM,6,FALSE),"") -> 95826.3 | AS3: =IFERROR(VLOOKUP(M3,BASFC,6,FALSE),"") -> 2189668.9 | AT3: =IFERROR(VLOOKUP(M3,Basilee24,7,FALSE),"") -> 927780.34 | AU3: =AW3-AV3 -> 988494.16 | AV3: =IFERROR(VLOOKUP(M3,BASALIM,7,FALSE),"") -> 17818.1 | AW3: =IFERROR(VLOOKUP(M3,BASFC,7,FALSE),"") -> 1006312.3 | AX3: =IFERROR(VLOOKUP(M3,Basilee24,8,FALSE),"") -> 1193080.1 | AY3: =BA3-AZ3 -> 1058755 | AZ3: =IFERROR(VLOOKUP(M3,BASALIM,8,FALSE),"") -> 51107.36 | BA3: =IFERROR(VLOOKUP(M3,BASFC,8,FALSE),"") -> 1109862.3 | BB3: =BH3+AY3+AU3 -> 3002805.4 | BC3: =BI3+AZ3+AV3 -> 68925.46 | BD3: =BJ3+BA3+AW3 -> 3071730.8 | BE3: =BB3+AL3 -> 5015255.2 | BF3: =BC3+AK3 -> 97962.9 | BG3: =SUM(BD3+AM3) -> 5113218.1 | BH3: =BJ3-BI3 -> 955556.24 | BI3: =IFERROR(VLOOKUP(M3,BASALIM,9,FALSE),"") -> 0 | BJ3: =IFERROR(VLOOKUP(M3,BASFC,9,FALSE),"") -> 955556.24 | BK3: =IFERROR(VLOOKUP(M3,Basilee24,10,FALSE),"") -> 0 | BL3: =BN3-BM3 -> 1606601.3 | BM3: =IFERROR(VLOOKUP(M3,BASALIM,10,FALSE),"") -> 17086.75 | BN3: =IFERROR(VLOOKUP(M3,BASFC,10,FALSE),"") -> 1623688 | BO3: =IFERROR(VLOOKUP(M3,Basilee24,11,FALSE),"") -> 393776.97 | BP3: =BR3-BQ3 -> 1618113.6 | BQ3: =IFERROR(VLOOKUP(M3,BASALIM,11,FALSE),"") -> 0 | BR3: =IFERROR(VLOOKUP(M3,BASFC,11,FALSE),"") -> 1618113.6 | BS3: =BH3+BL3+BP3 -> 4180271.1 | BT3: =SUM(BI3,BM3,BQ3) -> 17086.75 | BU3: =SUM(BJ3,BN3,BR3) -> 4197357.9 | BV3: =IFERROR(VLOOKUP(M3,Basilee24,12,FALSE),"") -> 2735282.9 | BW3: =BY3-BX3 -> 2187081.9 | BX3: =IFERROR(VLOOKUP(M3,BASALIM,12,FALSE),"") -> 0 | BY3: =IFERROR(VLOOKUP(M3,BASFC,12,FALSE),"") -> 2187081.9 | BZ3: =IFERROR(VLOOKUP(M3,Basilee24,13,FALSE),"") -> 747842.66 | CD3: =IFERROR(VLOOKUP(M3,Basilee24,14,FALSE),"") -> 0 | CI3: 0.15 | CJ3: 11 | CK3: 10 | CL3: 11 | CM3: 11 | CN3: 10 | CO3: 10 | CP3: 10 | CQ3: 11 | CR3: 11 | CS3: 11 | CT3: 10 | CU3: 11 | CV3: 11 | CW3: 11
A4: =VLOOKUP(M4,BASCART4,3,FALSE) -> 112014520 | B4: =VLOOKUP(M4,BASILECARTERA,2,FALSE) -> 38 | C4: =IFERROR(VLOOKUP(B4,DES,2,FALSE),"") -> 0.15 | D4: =IFERROR(VLOOKUP(B4,DES,3,FALSE),"") -> 0.26 | E4: =IFERROR(VLOOKUP(B4,DES,4,FALSE),"") -> 0 | F4: =VLOOKUP(M4,BASILECART2,2,FALSE) -> 38 | G4: =IFERROR(VLOOKUP(F4,DES,2,FALSE),"") -> 0.15 | H4: =IFERROR(VLOOKUP(F4,DES,3,FALSE),"") -> 0.26 | I4: =IFERROR(VLOOKUP(F4,DES,4,FALSE),"") -> 0 | J4: =VLOOKUP(M4,BASCART4,2,FALSE) -> 52 | K4: =IFERROR(VLOOKUP(J4,A458DC1025,2,FALSE),"") -> 0.15 | L4: =IFERROR(VLOOKUP(J4,A458DC1025,3,FALSE),"") -> 0.17 | M4: PIEDROZZI MARCOS/HIGA | N4: =IFERROR(VLOOKUP(M4,Basilee24,3,FALSE),"") | O4: =(N4*1.601)*1.05 -> #VALUE! | P4: =R4-Q4 -> 5711147.8 | Q4: =IFERROR(VLOOKUP(M4,BASALIM,3,FALSE),"") -> 30335362 | R4: =IFERROR(VLOOKUP(M4,BASFC,3,FALSE),"") -> 36046509 | S4: =R4-O4 -> #VALUE! | T4: =R4/O4 -> #VALUE! | U4: =IFERROR(VLOOKUP(M4,Basilee24,4,FALSE),"") | V4: =U4*1.7245 -> #VALUE! | W4: =Y4-X4 -> 17722887 | X4: =IFERROR(VLOOKUP(M4,BASALIM,4,FALSE),"") -> 17654908 | Y4: =IFERROR(VLOOKUP(M4,BASFC,4,FALSE),"") -> 35377795 | Z4: =Y4-V4 -> #VALUE! | AA4: =Y4/V4 -> #VALUE! | AB4: =IFERROR(VLOOKUP(M4,Basilee24,5,FALSE),"") | AC4: =(AB4*1.5955)*1.03 -> #VALUE! | AD4: =AF4-AE4 -> 211657.73 | AE4: =IFERROR(VLOOKUP(M4,BASALIM,5,FALSE),"") -> 33261060 | AF4: =IFERROR(VLOOKUP(M4,BASFC,5,FALSE),"") -> 33472717 | AG4: =AF4-AC4 -> #VALUE! | AH4: =AF4/AC4 -> #VALUE! | AI4: =SUM(O4,V4,AC4) -> #VALUE! | AJ4: =IFERROR(VLOOKUP(M4,trim2024,2,FALSE),"0") -> 0 | AK4: =SUM(AE4,X4,Q4) -> 81251329 | AL4: =SUM(P4,W4,AD4) -> 23645692 | AM4: =AF4+Y4+R4 -> 1.0489702e+08 | AN4: =AM4-AJ4 -> 1.0489702e+08 | AO4: =AM4/AJ4 -> #DIV/0! | AP4: =IFERROR(VLOOKUP(M4,Basilee24,6,FALSE),"") | AQ4: =AS4-AR4 -> 3645409.7 | AR4: =IFERROR(VLOOKUP(M4,BASALIM,6,FALSE),"") -> 31559592 | AS4: =IFERROR(VLOOKUP(M4,BASFC,6,FALSE),"") -> 35205001 | AT4: =IFERROR(VLOOKUP(M4,Basilee24,7,FALSE),"") | AU4: =AW4-AV4 -> 14734201 | AV4: =IFERROR(VLOOKUP(M4,BASALIM,7,FALSE),"") -> 34803454 | AW4: =IFERROR(VLOOKUP(M4,BASFC,7,FALSE),"") -> 49537655 | AX4: =IFERROR(VLOOKUP(M4,Basilee24,8,FALSE),"") | AY4: =BA4-AZ4 -> 9104628.5 | AZ4: =IFERROR(VLOOKUP(M4,BASALIM,8,FALSE),"") -> 27162655 | BA4: =IFERROR(VLOOKUP(M4,BASFC,8,FALSE),"") -> 36267284 | BB4: =BH4+AY4+AU4 -> 24239437 | BC4: =BI4+AZ4+AV4 -> 84567752 | BD4: =BJ4+BA4+AW4 -> 1.0880719e+08 | BE4: =BB4+AL4 -> 47885129 | BF4: =BC4+AK4 -> 1.6581908e+08 | BG4: =SUM(BD4+AM4) -> 2.1370421e+08 | BH4: =BJ4-BI4 -> 400607.58 | BI4: =IFERROR(VLOOKUP(M4,BASALIM,9,FALSE),"") -> 22601643 | BJ4: =IFERROR(VLOOKUP(M4,BASFC,9,FALSE),"") -> 23002250 | BK4: =IFERROR(VLOOKUP(M4,Basilee24,10,FALSE),"") | BL4: =BN4-BM4 -> 1023032.6 | BM4: =IFERROR(VLOOKUP(M4,BASALIM,10,FALSE),"") -> 16261281 | BN4: =IFERROR(VLOOKUP(M4,BASFC,10,FALSE),"") -> 17284313 | BO4: =IFERROR(VLOOKUP(M4,Basilee24,11,FALSE),"") | BP4: =BR4-BQ4 -> 5219352.1 | BQ4: =IFERROR(VLOOKUP(M4,BASALIM,11,FALSE),"") -> 25511912 | BR4: =IFERROR(VLOOKUP(M4,BASFC,11,FALSE),"") -> 30731265 | BS4: =BH4+BL4+BP4 -> 6642992.3 | BT4: =SUM(BI4,BM4,BQ4) -> 64374836 | BU4: =SUM(BJ4,BN4,BR4) -> 71017828 | BV4: =IFERROR(VLOOKUP(M4,Basilee24,12,FALSE),"") | BW4: =BY4-BX4 -> 6530036.8 | BX4: =IFERROR(VLOOKUP(M4,BASALIM,12,FALSE),"") -> 13466687 | BY4: =IFERROR(VLOOKUP(M4,BASFC,12,FALSE),"") -> 19996724 | BZ4: =IFERROR(VLOOKUP(M4,Basilee24,13,FALSE),"") | CD4: =IFERROR(VLOOKUP(M4,Basilee24,14,FALSE),"") | CI4: 0.12 | CK4: 3 | CL4: 3 | CM4: 0 | CN4: 0 | CO4: 0 | CP4: 1 | CQ4: 1 | CR4: 1 | CS4: 1
A5: =VLOOKUP(M5,BASCART4,3,FALSE) -> 112014235 | B5: =VLOOKUP(M5,BASILECARTERA,2,FALSE) -> 38 | C5: =IFERROR(VLOOKUP(B5,DES,2,FALSE),"") -> 0.15 | D5: =IFERROR(VLOOKUP(B5,DES,3,FALSE),"") -> 0.26 | E5: =IFERROR(VLOOKUP(B5,DES,4,FALSE),"") -> 0 | F5: =VLOOKUP(M5,BASILECART2,2,FALSE) -> 38 | G5: =IFERROR(VLOOKUP(F5,DES,2,FALSE),"") -> 0.15 | H5: =IFERROR(VLOOKUP(F5,DES,3,FALSE),"") -> 0.26 | I5: =IFERROR(VLOOKUP(F5,DES,4,FALSE),"") -> 0 | J5: =VLOOKUP(M5,BASCART4,2,FALSE) -> 52 | K5: =IFERROR(VLOOKUP(J5,A458DC1025,2,FALSE),"") -> 0.15 | L5: =IFERROR(VLOOKUP(J5,A458DC1025,3,FALSE),"") -> 0.17 | M5: NUTRIVALENT/ NUTRIVALENT SUC2/ VERGARA | N5: =IFERROR(VLOOKUP(M5,Basilee24,3,FALSE),"") -> 14230057 | O5: =(N5*1.601)*1.05 -> 23921437 | P5: =R5-Q5 -> 1416831 | Q5: =IFERROR(VLOOKUP(M5,BASALIM,3,FALSE),"") -> 21262272 | R5: =IFERROR(VLOOKUP(M5,BASFC,3,FALSE),"") -> 22679103 | S5: =R5-O5 -> -1242333.5 | T5: =R5/O5 -> 0.9480661 | U5: =IFERROR(VLOOKUP(M5,Basilee24,4,FALSE),"") -> 14727078 | V5: =U5*1.7245 -> 25396846 | W5: =Y5-X5 -> 1819323 | X5: =IFERROR(VLOOKUP(M5,BASALIM,4,FALSE),"") -> 29364223 | Y5: =IFERROR(VLOOKUP(M5,BASFC,4,FALSE),"") -> 31183546 | Z5: =Y5-V5 -> 5786699.7 | AA5: =Y5/V5 -> 1.2278511 | AB5: =IFERROR(VLOOKUP(M5,Basilee24,5,FALSE),"") -> 27181917 | AC5: =(AB5*1.5955)*1.03 -> 44669811 | AD5: =AF5-AE5 -> 1221067.5 | AE5: =IFERROR(VLOOKUP(M5,BASALIM,5,FALSE),"") -> 23470678 | AF5: =IFERROR(VLOOKUP(M5,BASFC,5,FALSE),"") -> 24691745 | AG5: =AF5-AC5 -> -19978066 | AH5: =AF5/AC5 -> 0.55276136 | AI5: =SUM(O5,V5,AC5) -> 93988093 | AJ5: =IFERROR(VLOOKUP(M5,trim2024,2,FALSE),"0") -> 97043915 | AK5: =SUM(AE5,X5,Q5) -> 74097173 | AL5: =SUM(P5,W5,AD5) -> 4457221.5 | AM5: =AF5+Y5+R5 -> 78554394 | AN5: =AM5-AJ5 -> -18489521 | AO5: =AM5/AJ5 -> 0.80947264 | AP5: =IFERROR(VLOOKUP(M5,Basilee24,6,FALSE),"") -> 25421451 | AQ5: =AS5-AR5 -> 1061367.4 | AR5: =IFERROR(VLOOKUP(M5,BASALIM,6,FALSE),"") -> 34398020 | AS5: =IFERROR(VLOOKUP(M5,BASFC,6,FALSE),"") -> 35459387 | AT5: =IFERROR(VLOOKUP(M5,Basilee24,7,FALSE),"") -> 18456604 | AU5: =AW5-AV5 -> 707578.25 | AV5: =IFERROR(VLOOKUP(M5,BASALIM,7,FALSE),"") -> 35477507 | AW5: =IFERROR(VLOOKUP(M5,BASFC,7,FALSE),"") -> 36185086 | AX5: =IFERROR(VLOOKUP(M5,Basilee24,8,FALSE),"") -> 21238449 | AY5: =BA5-AZ5 -> 249543 | AZ5: =IFERROR(VLOOKUP(M5,BASALIM,8,FALSE),"") -> 42774868 | BA5: =IFERROR(VLOOKUP(M5,BASFC,8,FALSE),"") -> 43024411 | BB5: =BH5+AY5+AU5 -> 1243269.5 | BC5: =BI5+AZ5+AV5 -> 1.2186922e+08 | BD5: =BJ5+BA5+AW5 -> 1.2311249e+08 | BE5: =BB5+AL5 -> 5700491 | BF5: =BC5+AK5 -> 1.959664e+08 | BG5: =SUM(BD5+AM5) -> 2.0166689e+08 | BH5: =BJ5-BI5 -> 286148.25 | BI5: =IFERROR(VLOOKUP(M5,BASALIM,9,FALSE),"") -> 43616849 | BJ5: =IFERROR(VLOOKUP(M5,BASFC,9,FALSE),"") -> 43902998 | BK5: =IFERROR(VLOOKUP(M5,Basilee24,10,FALSE),"") -> 33141853 | BL5: =BN5-BM5 -> 1650887.3 | BM5: =IFERROR(VLOOKUP(M5,BASALIM,10,FALSE),"") -> 55811631 | BN5: =IFERROR(VLOOKUP(M5,BASFC,10,FALSE),"") -> 57462518 | BO5: =IFERROR(VLOOKUP(M5,Basilee24,11,FALSE),"") -> 20627958 | BP5: =BR5-BQ5 -> 2383671.7 | BQ5: =IFERROR(VLOOKUP(M5,BASALIM,11,FALSE),"") -> 9042218 | BR5: =IFERROR(VLOOKUP(M5,BASFC,11,FALSE),"") -> 11425890 | BS5: =BH5+BL5+BP5 -> 4320707.3 | BT5: =SUM(BI5,BM5,BQ5) -> 1.084707e+08 | BU5: =SUM(BJ5,BN5,BR5) -> 1.1279141e+08 | BV5: =IFERROR(VLOOKUP(M5,Basilee24,12,FALSE),"") -> 27477443 | BW5: =BY5-BX5 -> 968840.29 | BX5: =IFERROR(VLOOKUP(M5,BASALIM,12,FALSE),"") -> 282201.93 | BY5: =IFERROR(VLOOKUP(M5,BASFC,12,FALSE),"") -> 1251042.2 | BZ5: =IFERROR(VLOOKUP(M5,Basilee24,13,FALSE),"") -> 27210427 | CD5: =IFERROR(VLOOKUP(M5,Basilee24,14,FALSE),"") -> 42356045 | CI5: 0.1 | CJ5: 24 | CK5: 18 | CL5: 18 | CM5: 27 | CN5: 30 | CO5: 31 | CP5: 33 | CQ5: 33 | CR5: 34 | CS5: 34 | CT5: 23 | CU5: 23 | CV5: 25 | CW5: 24
A6: =VLOOKUP(M6,BASCART4,3,FALSE) -> 112012275 | B6: =VLOOKUP(M6,BASILECARTERA,2,FALSE) -> 10 | C6: =IFERROR(VLOOKUP(B6,DES,2,FALSE),"") -> 0.15 | D6: =IFERROR(VLOOKUP(B6,DES,3,FALSE),"") -> 0.23 | E6: =IFERROR(VLOOKUP(B6,DES,4,FALSE),"") -> 0 | F6: =VLOOKUP(M6,BASILECART2,2,FALSE) -> 10 | G6: =IFERROR(VLOOKUP(F6,DES,2,FALSE),"") -> 0.15 | H6: =IFERROR(VLOOKUP(F6,DES,3,FALSE),"") -> 0.23 | I6: =IFERROR(VLOOKUP(F6,DES,4,FALSE),"") -> 0 | J6: =VLOOKUP(M6,BASCART4,2,FALSE) -> 53 | K6: =IFERROR(VLOOKUP(J6,A458DC1025,2,FALSE),"") -> 0.15 | L6: =IFERROR(VLOOKUP(J6,A458DC1025,3,FALSE),"") -> 0.14 | M6: HAKUNA MATATA/SUC 2 | N6: =IFERROR(VLOOKUP(M6,Basilee24,3,FALSE),"") -> 3625306.2 | O6: =(N6*1.601)*1.05 -> 6094321 | P6: =R6-Q6 -> 2024292.2 | Q6: =IFERROR(VLOOKUP(M6,BASALIM,3,FALSE),"") -> 6311486.4 | R6: =IFERROR(VLOOKUP(M6,BASFC,3,FALSE),"") -> 8335778.7 | S6: =R6-O6 -> 2241457.7 | T6: =R6/O6 -> 1.3677945 | U6: =IFERROR(VLOOKUP(M6,Basilee24,4,FALSE),"") -> 7557763.1 | V6: =U6*1.7245 -> 13033362 | W6: =Y6-X6 -> 4116637.3 | X6: =IFERROR(VLOOKUP(M6,BASALIM,4,FALSE),"") -> 6586208.9 | Y6: =IFERROR(VLOOKUP(M6,BASFC,4,FALSE),"") -> 10702846 | Z6: =Y6-V6 -> -2330516.2 | AA6: =Y6/V6 -> 0.82118841 | AB6: =IFERROR(VLOOKUP(M6,Basilee24,5,FALSE),"") -> 9972714.7 | AC6: =(AB6*1.5955)*1.03 -> 16388810 | AD6: =AF6-AE6 -> 1195291.5 | AE6: =IFERROR(VLOOKUP(M6,BASALIM,5,FALSE),"") -> 9468781.6 | AF6: =IFERROR(VLOOKUP(M6,BASFC,5,FALSE),"") -> 10664073 | AG6: =AF6-AC6 -> -5724737.2 | AH6: =AF6/AC6 -> 0.65069233 | AI6: =SUM(O6,V6,AC6) -> 35516494 | AJ6: =IFERROR(VLOOKUP(M6,trim2024,2,FALSE),"0") -> 24953340 | AK6: =SUM(AE6,X6,Q6) -> 22366477 | AL6: =SUM(P6,W6,AD6) -> 7336221 | AM6: =AF6+Y6+R6 -> 29702698 | AN6: =AM6-AJ6 -> 4749357.7 | AO6: =AM6/AJ6 -> 1.1903295 | AP6: =IFERROR(VLOOKUP(M6,Basilee24,6,FALSE),"") -> 4172537.6 | AQ6: =AS6-AR6 -> 1838991 | AR6: =IFERROR(VLOOKUP(M6,BASALIM,6,FALSE),"") -> 9753284.7 | AS6: =IFERROR(VLOOKUP(M6,BASFC,6,FALSE),"") -> 11592276 | AT6: =IFERROR(VLOOKUP(M6,Basilee24,7,FALSE),"") -> 8078157.9 | AU6: =AW6-AV6 -> 1902157.7 | AV6: =IFERROR(VLOOKUP(M6,BASALIM,7,FALSE),"") -> 11396690 | AW6: =IFERROR(VLOOKUP(M6,BASFC,7,FALSE),"") -> 13298847 | AX6: =IFERROR(VLOOKUP(M6,Basilee24,8,FALSE),"") -> 4165889.4 | AY6: =BA6-AZ6 -> 3090913.7 | AZ6: =IFERROR(VLOOKUP(M6,BASALIM,8,FALSE),"") -> 7683403.3 | BA6: =IFERROR(VLOOKUP(M6,BASFC,8,FALSE),"") -> 10774317 | BB6: =BH6+AY6+AU6 -> 8049822.5 | BC6: =BI6+AZ6+AV6 -> 28325850 | BD6: =BJ6+BA6+AW6 -> 36375673 | BE6: =BB6+AL6 -> 15386044 | BF6: =BC6+AK6 -> 50692327 | BG6: =SUM(BD6+AM6) -> 66078371 | BH6: =BJ6-BI6 -> 3056751.1 | BI6: =IFERROR(VLOOKUP(M6,BASALIM,9,FALSE),"") -> 9245757.5 | BJ6: =IFERROR(VLOOKUP(M6,BASFC,9,FALSE),"") -> 12302509 | BK6: =IFERROR(VLOOKUP(M6,Basilee24,10,FALSE),"") -> 4362355.7 | BL6: =BN6-BM6 -> 520176.75 | BM6: =IFERROR(VLOOKUP(M6,BASALIM,10,FALSE),"") -> 5940096.3 | BN6: =IFERROR(VLOOKUP(M6,BASFC,10,FALSE),"") -> 6460273 | BO6: =IFERROR(VLOOKUP(M6,Basilee24,11,FALSE),"") -> 5801888.6 | BP6: =BR6-BQ6 -> 187589.64 | BQ6: =IFERROR(VLOOKUP(M6,BASALIM,11,FALSE),"") -> 4420738 | BR6: =IFERROR(VLOOKUP(M6,BASFC,11,FALSE),"") -> 4608327.6 | BS6: =BH6+BL6+BP6 -> 3764517.5 | BT6: =SUM(BI6,BM6,BQ6) -> 19606592 | BU6: =SUM(BJ6,BN6,BR6) -> 23371109 | BV6: =IFERROR(VLOOKUP(M6,Basilee24,12,FALSE),"") -> 7359598 | BW6: =BY6-BX6 -> 296315.57 | BX6: =IFERROR(VLOOKUP(M6,BASALIM,12,FALSE),"") -> 4055629.4 | BY6: =IFERROR(VLOOKUP(M6,BASFC,12,FALSE),"") -> 4351944.9 | BZ6: =IFERROR(VLOOKUP(M6,Basilee24,13,FALSE),"") -> 8741529.3 | CD6: =IFERROR(VLOOKUP(M6,Basilee24,14,FALSE),"") -> 8852212.9 | CI6: 0.05 | CK6: 4 | CL6: 4 | CM6: 4 | CN6: 3 | CO6: 3 | CP6: 3 | CQ6: 3 | CR6: 3 | CS6: 3 | CT6: 1 | CU6: 1
A7: =VLOOKUP(M7,BASCART4,3,FALSE) -> 112014605 | B7: =VLOOKUP(M7,BASILECARTERA,2,FALSE) -> 10 | C7: =IFERROR(VLOOKUP(B7,DES,2,FALSE),"") -> 0.15 | D7: =IFERROR(VLOOKUP(B7,DES,3,FALSE),"") -> 0.23 | E7: =IFERROR(VLOOKUP(B7,DES,4,FALSE),"") -> 0 | F7: =VLOOKUP(M7,BASILECART2,2,FALSE) -> 10 | G7: =IFERROR(VLOOKUP(F7,DES,2,FALSE),"") -> 0.15 | H7: =IFERROR(VLOOKUP(F7,DES,3,FALSE),"") -> 0.23 | I7: =IFERROR(VLOOKUP(F7,DES,4,FALSE),"") -> 0 | J7: =VLOOKUP(M7,BASCART4,2,FALSE) -> 53 | K7: =IFERROR(VLOOKUP(J7,A458DC1025,2,FALSE),"") -> 0.15 | L7: =IFERROR(VLOOKUP(J7,A458DC1025,3,FALSE),"") -> 0.14 | M7: FORTUNATO EMILIANO ANGEL | N7: =IFERROR(VLOOKUP(M7,Basilee24,3,FALSE),"") | O7: 3000000 | P7: =R7-Q7 -> #VALUE! | Q7: =IFERROR(VLOOKUP(M7,BASALIM,3,FALSE),"") | R7: =IFERROR(VLOOKUP(M7,BASFC,3,FALSE),"") -> 0 | S7: =R7-O7 -> -3000000 | T7: =R7/O7 -> 0 | U7: =IFERROR(VLOOKUP(M7,Basilee24,4,FALSE),"") | V7: 3000000 | W7: =Y7-X7 -> #VALUE! | X7: =IFERROR(VLOOKUP(M7,BASALIM,4,FALSE),"") | Y7: =IFERROR(VLOOKUP(M7,BASFC,4,FALSE),"") -> 2964403.4 | Z7: =Y7-V7 -> -35596.63 | AA7: =Y7/V7 -> 0.98813446 | AB7: =IFERROR(VLOOKUP(M7,Basilee24,5,FALSE),"") | AC7: 3000000 | AD7: =AF7-AE7 -> #VALUE! | AE7: =IFERROR(VLOOKUP(M7,BASALIM,5,FALSE),"") | AF7: =IFERROR(VLOOKUP(M7,BASFC,5,FALSE),"") -> 101143.2 | AG7: =AF7-AC7 -> -2898856.8 | AH7: =AF7/AC7 -> 0.0337144 | AI7: =SUM(O7,V7,AC7) -> 9000000 | AJ7: =IFERROR(VLOOKUP(M7,trim2024,2,FALSE),"0") -> 0 | AK7: =SUM(AE7,X7,Q7) -> 0 | AL7: =SUM(P7,W7,AD7) -> #VALUE! | AM7: =AF7+Y7+R7 -> 3065546.6 | AN7: =AM7-AJ7 -> 3065546.6 | AO7: =AM7/AJ7 -> #DIV/0! | AP7: =IFERROR(VLOOKUP(M7,Basilee24,6,FALSE),"") | AQ7: =AS7-AR7 -> #VALUE! | AR7: =IFERROR(VLOOKUP(M7,BASALIM,6,FALSE),"") | AS7: =IFERROR(VLOOKUP(M7,BASFC,6,FALSE),"") -> 0 | AT7: =IFERROR(VLOOKUP(M7,Basilee24,7,FALSE),"") | AU7: =AW7-AV7 -> #VALUE! | AV7: =IFERROR(VLOOKUP(M7,BASALIM,7,FALSE),"") | AW7: =IFERROR(VLOOKUP(M7,BASFC,7,FALSE),"") -> 0 | AX7: =IFERROR(VLOOKUP(M7,Basilee24,8,FALSE),"") | AY7: =BA7-AZ7 -> #VALUE! | AZ7: =IFERROR(VLOOKUP(M7,BASALIM,8,FALSE),"") | BA7: =IFERROR(VLOOKUP(M7,BASFC,8,FALSE),"") -> 0 | BB7: =BH7+AY7+AU7 -> #VALUE! | BC7: =BI7+AZ7+AV7 -> #VALUE! | BD7: =BJ7+BA7+AW7 -> 0 | BE7: =BB7+AL7 -> #VALUE! | BF7: =BC7+AK7 -> #VALUE! | BG7: =SUM(BD7+AM7) -> 3065546.6 | BH7: =BJ7-BI7 -> #VALUE! | BI7: =IFERROR(VLOOKUP(M7,BASALIM,9,FALSE),"") | BJ7: =IFERROR(VLOOKUP(M7,BASFC,9,FALSE),"") -> 0 | BK7: =IFERROR(VLOOKUP(M7,Basilee24,10,FALSE),"") | BL7: =BN7-BM7 -> #VALUE! | BM7: =IFERROR(VLOOKUP(M7,BASALIM,10,FALSE),"") | BN7: =IFERROR(VLOOKUP(M7,BASFC,10,FALSE),"") -> 1718749.2 | BO7: =IFERROR(VLOOKUP(M7,Basilee24,11,FALSE),"") | BP7: =BR7-BQ7 -> #VALUE! | BQ7: =IFERROR(VLOOKUP(M7,BASALIM,11,FALSE),"") | BR7: =IFERROR(VLOOKUP(M7,BASFC,11,FALSE),"") -> 2550720.8 | BS7: =BH7+BL7+BP7 -> #VALUE! | BT7: =SUM(BI7,BM7,BQ7) -> 0 | BU7: =SUM(BJ7,BN7,BR7) -> 4269470 | BV7: =IFERROR(VLOOKUP(M7,Basilee24,12,FALSE),"") | BW7: =BY7-BX7 -> #VALUE! | BX7: =IFERROR(VLOOKUP(M7,BASALIM,12,FALSE),"") | BY7: =IFERROR(VLOOKUP(M7,BASFC,12,FALSE),"") -> 4341473.1 | BZ7: =IFERROR(VLOOKUP(M7,Basilee24,13,FALSE),"") | CD7: =IFERROR(VLOOKUP(M7,Basilee24,14,FALSE),"") | CI7: SIN | CJ7: 114 | CK7: 86 | CL7: 85 | CM7: 98 | CN7: 96 | CO7: 95 | CP7: 94 | CQ7: 94 | CR7: 94 | CS7: 95 | CT7: 111 | CU7: 114 | CV7: 116 | CW7: 114
A8: =VLOOKUP(M8,BASCART4,3,FALSE) -> 112013867 | B8: =VLOOKUP(M8,BASILECARTERA,2,FALSE) -> 12 | C8: =IFERROR(VLOOKUP(B8,DES,2,FALSE),"") -> 0.15 | D8: =IFERROR(VLOOKUP(B8,DES,3,FALSE),"") -> 0.09 | E8: =IFERROR(VLOOKUP(B8,DES,4,FALSE),"") -> 0 | F8: =VLOOKUP(M8,BASILECART2,2,FALSE) -> 12 | G8: =IFERROR(VLOOKUP(F8,DES,2,FALSE),"") -> 0.15 | H8: =IFERROR(VLOOKUP(F8,DES,3,FALSE),"") -> 0.09 | I8: =IFERROR(VLOOKUP(F8,DES,4,FALSE),"") -> 0 | J8: =VLOOKUP(M8,BASCART4,2,FALSE) -> 55 | K8: =IFERROR(VLOOKUP(J8,A458DC1025,2,FALSE),"") -> 0.15 | L8: =IFERROR(VLOOKUP(J8,A458DC1025,3,FALSE),"") -> 0.05 | M8: DURAN SERGIO DANIEL | N8: =IFERROR(VLOOKUP(M8,Basilee24,3,FALSE),"") -> 2146107 | O8: =(N8*1.601)*1.05 -> 3607713.1 | P8: =R8-Q8 -> #VALUE! | Q8: =IFERROR(VLOOKUP(M8,BASALIM,3,FALSE),"") | R8: =IFERROR(VLOOKUP(M8,BASFC,3,FALSE),"") -> 5413003.3 | S8: =R8-O8 -> 1805290.1 | T8: =R8/O8 -> 1.5003974 | U8: =IFERROR(VLOOKUP(M8,Basilee24,4,FALSE),"") -> 1009713.9 | V8: 3000000 | W8: =Y8-X8 -> #VALUE! | X8: =IFERROR(VLOOKUP(M8,BASALIM,4,FALSE),"") | Y8: =IFERROR(VLOOKUP(M8,BASFC,4,FALSE),"") -> 2353881 | Z8: =Y8-V8 -> -646119.05 | AA8: =Y8/V8 -> 0.78462698 | AB8: =IFERROR(VLOOKUP(M8,Basilee24,5,FALSE),"") -> 1230548.7 | AC8: 3000000 | AD8: =AF8-AE8 -> #VALUE! | AE8: =IFERROR(VLOOKUP(M8,BASALIM,5,FALSE),"") | AF8: =IFERROR(VLOOKUP(M8,BASFC,5,FALSE),"") -> 3042748.2 | AG8: =AF8-AC8 -> 42748.21 | AH8: =AF8/AC8 -> 1.0142494 | AI8: =SUM(O8,V8,AC8) -> 9607713.1 | AJ8: =IFERROR(VLOOKUP(M8,trim2024,2,FALSE),"0") -> 14303963 | AK8: =SUM(AE8,X8,Q8) -> 0 | AL8: =SUM(P8,W8,AD8) -> #VALUE! | AM8: =AF8+Y8+R8 -> 10809632 | AN8: =AM8-AJ8 -> -3494330.5 | AO8: =AM8/AJ8 -> 0.75570892 | AP8: =IFERROR(VLOOKUP(M8,Basilee24,6,FALSE),"") -> 703328.37 | AQ8: =AS8-AR8 -> #VALUE! | AR8: =IFERROR(VLOOKUP(M8,BASALIM,6,FALSE),"") | AS8: =IFERROR(VLOOKUP(M8,BASFC,6,FALSE),"") -> 2455587.4 | AT8: =IFERROR(VLOOKUP(M8,Basilee24,7,FALSE),"") -> 1141074.9 | AU8: =AW8-AV8 -> #VALUE! | AV8: =IFERROR(VLOOKUP(M8,BASALIM,7,FALSE),"") | AW8: =IFERROR(VLOOKUP(M8,BASFC,7,FALSE),"") -> 2172851.1 | AX8: =IFERROR(VLOOKUP(M8,Basilee24,8,FALSE),"") -> 1264239.2 | AY8: =BA8-AZ8 -> #VALUE! | AZ8: =IFERROR(VLOOKUP(M8,BASALIM,8,FALSE),"") | BA8: =IFERROR(VLOOKUP(M8,BASFC,8,FALSE),"") -> 2052576.5 | BB8: =BH8+AY8+AU8 -> #VALUE! | BC8: =BI8+AZ8+AV8 -> #VALUE! | BD8: =BJ8+BA8+AW8 -> 5253472.3 | BE8: =BB8+AL8 -> #VALUE! | BF8: =BC8+AK8 -> #VALUE! | BG8: =SUM(BD8+AM8) -> 16063105 | BH8: =BJ8-BI8 -> #VALUE! | BI8: =IFERROR(VLOOKUP(M8,BASALIM,9,FALSE),"") | BJ8: =IFERROR(VLOOKUP(M8,BASFC,9,FALSE),"") -> 1028044.8 | BK8: =IFERROR(VLOOKUP(M8,Basilee24,10,FALSE),"") -> 2084940.8 | BL8: =BN8-BM8 -> #VALUE! | BM8: =IFERROR(VLOOKUP(M8,BASALIM,10,FALSE),"") | BN8: =IFERROR(VLOOKUP(M8,BASFC,10,FALSE),"") -> 1129663.3 | BO8: =IFERROR(VLOOKUP(M8,Basilee24,11,FALSE),"") -> 1661952.3 | BP8: =BR8-BQ8 -> #VALUE! | BQ8: =IFERROR(VLOOKUP(M8,BASALIM,11,FALSE),"") | BR8: =IFERROR(VLOOKUP(M8,BASFC,11,FALSE),"") -> 2916085.3 | BS8: =BH8+BL8+BP8 -> #VALUE! | BT8: =SUM(BI8,BM8,BQ8) -> 0 | BU8: =SUM(BJ8,BN8,BR8) -> 5073793.3 | BV8: =IFERROR(VLOOKUP(M8,Basilee24,12,FALSE),"") -> 4568330.6 | BW8: =BY8-BX8 -> #VALUE! | BX8: =IFERROR(VLOOKUP(M8,BASALIM,12,FALSE),"") | BY8: =IFERROR(VLOOKUP(M8,BASFC,12,FALSE),"") -> 5802249.7 | BZ8: =IFERROR(VLOOKUP(M8,Basilee24,13,FALSE),"") -> 4468315.2 | CD8: =IFERROR(VLOOKUP(M8,Basilee24,14,FALSE),"") -> 5267317.1 | CI8: TOTAL: | CJ8: =SUM(CJ2:CJ7) -> 149 | CK8: =SUM(CK2:CK7) -> 121 | CL8: =SUM(CL3:CL7) -> 121 | CM8: =SUM(CM3:CM7) -> 140 | CN8: =SUM(CN3:CN7) -> 139 | CO8: =SUM(CO3:CO7) -> 139 | CP8: =SUM(CP3:CP7) -> 141 | CQ8: =SUM(CQ3:CQ7) -> 142 | CR8: =SUM(CR3:CR7) -> 143 | CS8: =SUM(CS3:CS7) -> 144 | ... CU8: =SUM(CU3:CU7) -> 149 | CV8: =SUM(CV2:CV7) -> 153 | CW8: =SUM(CW2:CW7) -> 149
A9: =VLOOKUP(M9,BASCART4,3,FALSE) -> 112014558 | B9: =IFERROR(VLOOKUP(M9,BASILECARTERA,2,FALSE),"") | C9: =IFERROR(VLOOKUP(B9,DES,2,FALSE),"") | D9: =IFERROR(VLOOKUP(B9,DES,3,FALSE),"") | E9: =IFERROR(VLOOKUP(B9,DES,4,FALSE),"") | F9: =VLOOKUP(M9,BASILECART2,2,FALSE) -> 10 | G9: =IFERROR(VLOOKUP(F9,DES,2,FALSE),"") -> 0.15 | H9: =IFERROR(VLOOKUP(F9,DES,3,FALSE),"") -> 0.23 | I9: =IFERROR(VLOOKUP(F9,DES,4,FALSE),"") -> 0 | J9: =VLOOKUP(M9,BASCART4,2,FALSE) -> 53 | K9: =IFERROR(VLOOKUP(J9,A458DC1025,2,FALSE),"") -> 0.15 | L9: =IFERROR(VLOOKUP(J9,A458DC1025,3,FALSE),"") -> 0.14 | M9: VETERINARIA SAN MARTIN SA | N9: =IFERROR(VLOOKUP(M9,Basilee24,3,FALSE),"") | O9: =(N9*1.601)*1.05 -> #VALUE! | P9: =R9-Q9 -> #VALUE! | Q9: =IFERROR(VLOOKUP(M9,BASALIM,3,FALSE),"") | R9: =IFERROR(VLOOKUP(M9,BASFC,3,FALSE),"") -> 0 | S9: =R9-O9 -> #VALUE! | T9: =R9/O9 -> #VALUE! | U9: =IFERROR(VLOOKUP(M9,Basilee24,4,FALSE),"") | V9: 3000000 | W9: =Y9-X9 -> #VALUE! | X9: =IFERROR(VLOOKUP(M9,BASALIM,4,FALSE),"") | Y9: =IFERROR(VLOOKUP(M9,BASFC,4,FALSE),"") -> 0 | Z9: =Y9-V9 -> -3000000 | AA9: =Y9/V9 -> 0 | AB9: =IFERROR(VLOOKUP(M9,Basilee24,5,FALSE),"") | AC9: 3000000 | AD9: =AF9-AE9 -> #VALUE! | AE9: =IFERROR(VLOOKUP(M9,BASALIM,5,FALSE),"") | AF9: =IFERROR(VLOOKUP(M9,BASFC,5,FALSE),"") -> 0 | AG9: =AF9-AC9 -> -3000000 | AH9: =AF9/AC9 -> 0 | AI9: =SUM(O9,V9,AC9) -> #VALUE! | AJ9: =IFERROR(VLOOKUP(M9,trim2024,2,FALSE),"0") -> 0 | AK9: =SUM(AE9,X9,Q9) -> 0 | AL9: =SUM(P9,W9,AD9) -> #VALUE! | AM9: =AF9+Y9+R9 -> 0 | AN9: =AM9-AJ9 -> 0 | AO9: =AM9/AJ9 -> #DIV/0! | AP9: =IFERROR(VLOOKUP(M9,Basilee24,6,FALSE),"") | AQ9: =AS9-AR9 -> #VALUE! | AR9: =IFERROR(VLOOKUP(M9,BASALIM,6,FALSE),"") | AS9: =IFERROR(VLOOKUP(M9,BASFC,6,FALSE),"") -> 0 | AT9: =IFERROR(VLOOKUP(M9,Basilee24,7,FALSE),"") | AU9: =AW9-AV9 -> #VALUE! | AV9: =IFERROR(VLOOKUP(M9,BASALIM,7,FALSE),"") | AW9: =IFERROR(VLOOKUP(M9,BASFC,7,FALSE),"") -> 0 | AX9: =IFERROR(VLOOKUP(M9,Basilee24,8,FALSE),"") | AY9: =BA9-AZ9 -> #VALUE! | AZ9: =IFERROR(VLOOKUP(M9,BASALIM,8,FALSE),"") | BA9: =IFERROR(VLOOKUP(M9,BASFC,8,FALSE),"") -> 0 | BB9: =BH9+AY9+AU9 -> #VALUE! | BC9: =BI9+AZ9+AV9 -> #VALUE! | BD9: =BJ9+BA9+AW9 -> 0 | BE9: =BB9+AL9 -> #VALUE! | BF9: =BC9+AK9 -> #VALUE! | BG9: =SUM(BD9+AM9) -> 0 | BH9: =BJ9-BI9 -> #VALUE! | BI9: =IFERROR(VLOOKUP(M9,BASALIM,9,FALSE),"") | BJ9: =IFERROR(VLOOKUP(M9,BASFC,9,FALSE),"") -> 0 | BK9: =IFERROR(VLOOKUP(M9,Basilee24,10,FALSE),"") | BL9: =BN9-BM9 -> #VALUE! | BM9: =IFERROR(VLOOKUP(M9,BASALIM,10,FALSE),"") | BN9: =IFERROR(VLOOKUP(M9,BASFC,10,FALSE),"") -> 0 | BO9: =IFERROR(VLOOKUP(M9,Basilee24,11,FALSE),"") | BP9: =BR9-BQ9 -> #VALUE! | BQ9: =IFERROR(VLOOKUP(M9,BASALIM,11,FALSE),"") | BR9: =IFERROR(VLOOKUP(M9,BASFC,11,FALSE),"") -> 2983892.7 | BS9: =BH9+BL9+BP9 -> #VALUE! | BT9: =SUM(BI9,BM9,BQ9) -> 0 | BU9: =SUM(BJ9,BN9,BR9) -> 2983892.7 | BV9: =IFERROR(VLOOKUP(M9,Basilee24,12,FALSE),"") | BW9: =BY9-BX9 -> #VALUE! | BX9: =IFERROR(VLOOKUP(M9,BASALIM,12,FALSE),"") | BY9: =IFERROR(VLOOKUP(M9,BASFC,12,FALSE),"") -> 1943258.6 | BZ9: =IFERROR(VLOOKUP(M9,Basilee24,13,FALSE),"") | CD9: =IFERROR(VLOOKUP(M9,Basilee24,14,FALSE),"")
A10: =VLOOKUP(M10,BASCART4,3,FALSE) -> 112012843 | B10: =IFERROR(VLOOKUP(M10,BASILECARTERA,2,FALSE),"") -> 12 | C10: =IFERROR(VLOOKUP(B10,DES,2,FALSE),"") -> 0.15 | D10: =IFERROR(VLOOKUP(B10,DES,3,FALSE),"") -> 0.09 | E10: =IFERROR(VLOOKUP(B10,DES,4,FALSE),"") -> 0 | F10: =VLOOKUP(M10,BASILECART2,2,FALSE) -> 12 | G10: =IFERROR(VLOOKUP(F10,DES,2,FALSE),"") -> 0.15 | H10: =IFERROR(VLOOKUP(F10,DES,3,FALSE),"") -> 0.09 | I10: =IFERROR(VLOOKUP(F10,DES,4,FALSE),"") -> 0 | J10: =VLOOKUP(M10,BASCART4,2,FALSE) -> 55 | K10: =IFERROR(VLOOKUP(J10,A458DC1025,2,FALSE),"") -> 0.15 | L10: =IFERROR(VLOOKUP(J10,A458DC1025,3,FALSE),"") -> 0.05 | M10: AGROMERCADO CENTRAL/BALANCEAD DEL MERC | N10: =IFERROR(VLOOKUP(M10,Basilee24,3,FALSE),"") -> 3108853.5 | O10: =(N10*1.601)*1.05 -> 5226138.1 | P10: =R10-Q10 -> 7196480.1 | Q10: =IFERROR(VLOOKUP(M10,BASALIM,3,FALSE),"") -> 0 | R10: =IFERROR(VLOOKUP(M10,BASFC,3,FALSE),"") -> 7196480.1 | S10: =R10-O10 -> 1970341.9 | T10: =R10/O10 -> 1.3770168 | U10: =IFERROR(VLOOKUP(M10,Basilee24,4,FALSE),"") -> 302700.1 | V10: 3000000 | W10: =Y10-X10 -> 12594299 | X10: =IFERROR(VLOOKUP(M10,BASALIM,4,FALSE),"") -> 153322.08 | Y10: =IFERROR(VLOOKUP(M10,BASFC,4,FALSE),"") -> 12747621 | Z10: =Y10-V10 -> 9747621.2 | AA10: =Y10/V10 -> 4.2492071 | AB10: =IFERROR(VLOOKUP(M10,Basilee24,5,FALSE),"") -> 0 | AC10: 3000000 | AD10: =AF10-AE10 -> 1305404.9 | AE10: =IFERROR(VLOOKUP(M10,BASALIM,5,FALSE),"") -> 0 | AF10: =IFERROR(VLOOKUP(M10,BASFC,5,FALSE),"") -> 1305404.9 | AG10: =AF10-AC10 -> -1694595.1 | AH10: =AF10/AC10 -> 0.43513497 | AI10: =SUM(O10,V10,AC10) -> 11226138 | AJ10: =IFERROR(VLOOKUP(M10,trim2024,2,FALSE),"0") -> 82418715 | AK10: =SUM(AE10,X10,Q10) -> 153322.08 | AL10: =SUM(P10,W10,AD10) -> 21096184 | AM10: =AF10+Y10+R10 -> 21249506 | AN10: =AM10-AJ10 -> -61169209 | AO10: =AM10/AJ10 -> 0.2578238 | AP10: =IFERROR(VLOOKUP(M10,Basilee24,6,FALSE),"") -> 7604676.4 | AQ10: =AS10-AR10 -> 0 | AR10: =IFERROR(VLOOKUP(M10,BASALIM,6,FALSE),"") -> 0 | AS10: =IFERROR(VLOOKUP(M10,BASFC,6,FALSE),"") -> 0 | AT10: =IFERROR(VLOOKUP(M10,Basilee24,7,FALSE),"") -> 58563252 | AU10: =AW10-AV10 -> 13078708 | AV10: =IFERROR(VLOOKUP(M10,BASALIM,7,FALSE),"") -> 0 | AW10: =IFERROR(VLOOKUP(M10,BASFC,7,FALSE),"") -> 13078708 | AX10: =IFERROR(VLOOKUP(M10,Basilee24,8,FALSE),"") -> 0 | AY10: =BA10-AZ10 -> 2988980.7 | AZ10: =IFERROR(VLOOKUP(M10,BASALIM,8,FALSE),"") -> 0 | BA10: =IFERROR(VLOOKUP(M10,BASFC,8,FALSE),"") -> 2988980.7 | BB10: =BH10+AY10+AU10 -> 16841486 | BC10: =BI10+AZ10+AV10 -> 0 | BD10: =BJ10+BA10+AW10 -> 16841486 | BE10: =BB10+AL10 -> 37937670 | BF10: =BC10+AK10 -> 153322.08 | BG10: =SUM(BD10+AM10) -> 38090992 | BH10: =BJ10-BI10 -> 773797.55 | BI10: =IFERROR(VLOOKUP(M10,BASALIM,9,FALSE),"") -> 0 | BJ10: =IFERROR(VLOOKUP(M10,BASFC,9,FALSE),"") -> 773797.55 | BK10: =IFERROR(VLOOKUP(M10,Basilee24,10,FALSE),"") -> 8667926 | BL10: =BN10-BM10 -> 3270032 | BM10: =IFERROR(VLOOKUP(M10,BASALIM,10,FALSE),"") -> 0 | BN10: =IFERROR(VLOOKUP(M10,BASFC,10,FALSE),"") -> 3270032 | BO10: =IFERROR(VLOOKUP(M10,Basilee24,11,FALSE),"") -> 3511697.7 | BP10: =BR10-BQ10 -> 1704569.4 | BQ10: =IFERROR(VLOOKUP(M10,BASALIM,11,FALSE),"") -> 0 | BR10: =IFERROR(VLOOKUP(M10,BASFC,11,FALSE),"") -> 1704569.4 | BS10: =BH10+BL10+BP10 -> 5748398.9 | BT10: =SUM(BI10,BM10,BQ10) -> 0 | BU10: =SUM(BJ10,BN10,BR10) -> 5748398.9 | BV10: =IFERROR(VLOOKUP(M10,Basilee24,12,FALSE),"") -> 10028174 | BW10: =BY10-BX10 -> 5869337.7 | BX10: =IFERROR(VLOOKUP(M10,BASALIM,12,FALSE),"") -> 0 | BY10: =IFERROR(VLOOKUP(M10,BASFC,12,FALSE),"") -> 5869337.7 | BZ10: =IFERROR(VLOOKUP(M10,Basilee24,13,FALSE),"") -> 40167348 | CD10: =IFERROR(VLOOKUP(M10,Basilee24,14,FALSE),"") -> 32223194
A11: =VLOOKUP(M11,BASCART4,3,FALSE) -> 112012311 | B11: =IFERROR(VLOOKUP(M11,BASILECARTERA,2,FALSE),"") -> 12 | C11: =IFERROR(VLOOKUP(B11,DES,2,FALSE),"") -> 0.15 | D11: =IFERROR(VLOOKUP(B11,DES,3,FALSE),"") -> 0.09 | E11: =IFERROR(VLOOKUP(B11,DES,4,FALSE),"") -> 0 | F11: =VLOOKUP(M11,BASILECART2,2,FALSE) -> 12 | G11: =IFERROR(VLOOKUP(F11,DES,2,FALSE),"") -> 0.15 | H11: =IFERROR(VLOOKUP(F11,DES,3,FALSE),"") -> 0.09 | I11: =IFERROR(VLOOKUP(F11,DES,4,FALSE),"") -> 0 | J11: =VLOOKUP(M11,BASCART4,2,FALSE) -> 55 | K11: =IFERROR(VLOOKUP(J11,A458DC1025,2,FALSE),"") -> 0.15 | L11: =IFERROR(VLOOKUP(J11,A458DC1025,3,FALSE),"") -> 0.05 | M11: ADROGUE JOSE/PEREYRA STELLA | N11: =IFERROR(VLOOKUP(M11,Basilee24,3,FALSE),"") -> 1407272.8 | O11: =(N11*1.601)*1.05 -> 2365695.9 | P11: =R11-Q11 -> 1907718.3 | Q11: =IFERROR(VLOOKUP(M11,BASALIM,3,FALSE),"") -> 0 | R11: =IFERROR(VLOOKUP(M11,BASFC,3,FALSE),"") -> 1907718.3 | S11: =R11-O11 -> -457977.61 | T11: =R11/O11 -> 0.80640892 | U11: =IFERROR(VLOOKUP(M11,Basilee24,4,FALSE),"") -> 834450.92 | V11: 3000000 | W11: =Y11-X11 -> 1840225.3 | X11: =IFERROR(VLOOKUP(M11,BASALIM,4,FALSE),"") -> 0 | Y11: =IFERROR(VLOOKUP(M11,BASFC,4,FALSE),"") -> 1840225.3 | Z11: =Y11-V11 -> -1159774.7 | AA11: =Y11/V11 -> 0.61340844 | AB11: =IFERROR(VLOOKUP(M11,Basilee24,5,FALSE),"") -> 1112505.4 | AC11: 3000000 | AD11: =AF11-AE11 -> 1672729.2 | AE11: =IFERROR(VLOOKUP(M11,BASALIM,5,FALSE),"") -> 0 | AF11: =IFERROR(VLOOKUP(M11,BASFC,5,FALSE),"") -> 1672729.2 | AG11: =AF11-AC11 -> -1327270.8 | AH11: =AF11/AC11 -> 0.55757641 | AI11: =SUM(O11,V11,AC11) -> 8365695.9 | AJ11: =IFERROR(VLOOKUP(M11,trim2024,2,FALSE),"0") -> 7115878.2 | AK11: =SUM(AE11,X11,Q11) -> 0 | AL11: =SUM(P11,W11,AD11) -> 5420672.8 | AM11: =AF11+Y11+R11 -> 5420672.8 | AN11: =AM11-AJ11 -> -1695205.4 | AO11: =AM11/AJ11 -> 0.76177144 | AP11: =IFERROR(VLOOKUP(M11,Basilee24,6,FALSE),"") -> 948238.82 | AQ11: =AS11-AR11 -> 1725528.7 | AR11: =IFERROR(VLOOKUP(M11,BASALIM,6,FALSE),"") -> 0 | AS11: =IFERROR(VLOOKUP(M11,BASFC,6,FALSE),"") -> 1725528.7 | AT11: =IFERROR(VLOOKUP(M11,Basilee24,7,FALSE),"") -> 1084593.3 | AU11: =AW11-AV11 -> 1827395.1 | AV11: =IFERROR(VLOOKUP(M11,BASALIM,7,FALSE),"") -> 0 | AW11: =IFERROR(VLOOKUP(M11,BASFC,7,FALSE),"") -> 1827395.1 | AX11: =IFERROR(VLOOKUP(M11,Basilee24,8,FALSE),"") -> 1218462.3 | AY11: =BA11-AZ11 -> 2093150.1 | AZ11: =IFERROR(VLOOKUP(M11,BASALIM,8,FALSE),"") -> 0 | BA11: =IFERROR(VLOOKUP(M11,BASFC,8,FALSE),"") -> 2093150.1 | BB11: =BH11+AY11+AU11 -> 4768682 | BC11: =BI11+AZ11+AV11 -> 6388.42 | BD11: =BJ11+BA11+AW11 -> 4775070.4 | BE11: =BB11+AL11 -> 10189355 | BF11: =BC11+AK11 -> 6388.42 | BG11: =SUM(BD11+AM11) -> 10195743 | BH11: =BJ11-BI11 -> 848136.73 | BI11: =IFERROR(VLOOKUP(M11,BASALIM,9,FALSE),"") -> 6388.42 | BJ11: =IFERROR(VLOOKUP(M11,BASFC,9,FALSE),"") -> 854525.15 | BK11: =IFERROR(VLOOKUP(M11,Basilee24,10,FALSE),"") -> 1561418.6 | BL11: =BN11-BM11 -> 2426548.5 | BM11: =IFERROR(VLOOKUP(M11,BASALIM,10,FALSE),"") -> 0 | BN11: =IFERROR(VLOOKUP(M11,BASFC,10,FALSE),"") -> 2426548.5 | BO11: =IFERROR(VLOOKUP(M11,Basilee24,11,FALSE),"") -> 1740717.5 | BP11: =BR11-BQ11 -> 1321466.4 | BQ11: =IFERROR(VLOOKUP(M11,BASALIM,11,FALSE),"") -> 0 | BR11: =IFERROR(VLOOKUP(M11,BASFC,11,FALSE),"") -> 1321466.4 | BS11: =BH11+BL11+BP11 -> 4596151.6 | BT11: =SUM(BI11,BM11,BQ11) -> 6388.42 | BU11: =SUM(BJ11,BN11,BR11) -> 4602540 | BV11: =IFERROR(VLOOKUP(M11,Basilee24,12,FALSE),"") -> 2391441 | BW11: =BY11-BX11 -> 3245674.1 | BX11: =IFERROR(VLOOKUP(M11,BASALIM,12,FALSE),"") -> 0 | BY11: =IFERROR(VLOOKUP(M11,BASFC,12,FALSE),"") -> 3245674.1 | BZ11: =IFERROR(VLOOKUP(M11,Basilee24,13,FALSE),"") -> 2092798.6 | CD11: =IFERROR(VLOOKUP(M11,Basilee24,14,FALSE),"") -> 2631638.7
A12: =VLOOKUP(M12,BASCART4,3,FALSE) -> 112014719 | B12: =IFERROR(VLOOKUP(M12,BASILECARTERA,2,FALSE),"") -> 10 | C12: =IFERROR(VLOOKUP(B12,DES,2,FALSE),"") -> 0.15 | D12: =IFERROR(VLOOKUP(B12,DES,3,FALSE),"") -> 0.23 | E12: =IFERROR(VLOOKUP(B12,DES,4,FALSE),"") -> 0 | F12: =VLOOKUP(M12,BASILECART2,2,FALSE) -> 10 | G12: =IFERROR(VLOOKUP(F12,DES,2,FALSE),"") -> 0.15 | H12: =IFERROR(VLOOKUP(F12,DES,3,FALSE),"") -> 0.23 | I12: =IFERROR(VLOOKUP(F12,DES,4,FALSE),"") -> 0 | J12: =VLOOKUP(M12,BASCART4,2,FALSE) -> 53 | K12: =IFERROR(VLOOKUP(J12,A458DC1025,2,FALSE),"") -> 0.15 | L12: =IFERROR(VLOOKUP(J12,A458DC1025,3,FALSE),"") -> 0.14 | M12: OLIVERI JORGE LUIS | N12: =IFERROR(VLOOKUP(M12,Basilee24,3,FALSE),"") | P12: =R12-Q12 -> #VALUE! | Q12: =IFERROR(VLOOKUP(M12,BASALIM,3,FALSE),"") | R12: =IFERROR(VLOOKUP(M12,BASFC,3,FALSE),"") -> 0 | S12: =R12-O12 -> 0 | T12: =R12/O12 -> #DIV/0! | U12: =IFERROR(VLOOKUP(M12,Basilee24,4,FALSE),"") | W12: =Y12-X12 -> #VALUE! | X12: =IFERROR(VLOOKUP(M12,BASALIM,4,FALSE),"") | Y12: =IFERROR(VLOOKUP(M12,BASFC,4,FALSE),"") -> 0 | Z12: =Y12-V12 -> 0 | AA12: =IFERROR(Y12/V12,"") | AB12: =IFERROR(VLOOKUP(M12,Basilee24,5,FALSE),"") | AD12: =AF12-AE12 -> #VALUE! | AE12: =IFERROR(VLOOKUP(M12,BASALIM,5,FALSE),"") | AF12: =IFERROR(VLOOKUP(M12,BASFC,5,FALSE),"") -> 0 | AG12: =AF12-AC12 -> 0 | AH12: =IFERROR(AF12/AC12,"") | AJ12: =IFERROR(VLOOKUP(M12,trim2024,2,FALSE),"0") -> 0 | AK12: =SUM(AE12,X12,Q12) -> 0 | AL12: =SUM(P12,W12,AD12) -> #VALUE! | AM12: =AF12+Y12+R12 -> 0 | AN12: =AM12-AJ12 -> 0 | AO12: =AM12/AJ12 -> #DIV/0! | AP12: =IFERROR(VLOOKUP(M12,Basilee24,6,FALSE),"") | AQ12: =AS12-AR12 -> #VALUE! | AR12: =IFERROR(VLOOKUP(M12,BASALIM,6,FALSE),"") | AS12: =IFERROR(VLOOKUP(M12,BASFC,6,FALSE),"") -> 0 | AT12: =IFERROR(VLOOKUP(M12,Basilee24,7,FALSE),"") | AU12: =AW12-AV12 -> #VALUE! | AV12: =IFERROR(VLOOKUP(M12,BASALIM,7,FALSE),"") | AW12: =IFERROR(VLOOKUP(M12,BASFC,7,FALSE),"") -> 0 | AX12: =IFERROR(VLOOKUP(M12,Basilee24,8,FALSE),"") | AY12: =BA12-AZ12 -> #VALUE! | AZ12: =IFERROR(VLOOKUP(M12,BASALIM,8,FALSE),"") | BA12: =IFERROR(VLOOKUP(M12,BASFC,8,FALSE),"") -> 0 | BB12: =BH12+AY12+AU12 -> #VALUE! | BC12: =BI12+AZ12+AV12 -> #VALUE! | BD12: =BJ12+BA12+AW12 -> 0 | BE12: =BB12+AL12 -> #VALUE! | BF12: =BC12+AK12 -> #VALUE! | BG12: =SUM(BD12+AM12) -> 0 | BH12: =BJ12-BI12 -> #VALUE! | BI12: =IFERROR(VLOOKUP(M12,BASALIM,9,FALSE),"") | BJ12: =IFERROR(VLOOKUP(M12,BASFC,9,FALSE),"") -> 0 | BK12: =IFERROR(VLOOKUP(M12,Basilee24,10,FALSE),"") | BL12: =BN12-BM12 -> #VALUE! | BM12: =IFERROR(VLOOKUP(M12,BASALIM,10,FALSE),"") | BN12: =IFERROR(VLOOKUP(M12,BASFC,10,FALSE),"") -> 9547806.5 | BO12: =IFERROR(VLOOKUP(M12,Basilee24,11,FALSE),"") | BP12: =BR12-BQ12 -> #VALUE! | BQ12: =IFERROR(VLOOKUP(M12,BASALIM,11,FALSE),"") | BR12: =IFERROR(VLOOKUP(M12,BASFC,11,FALSE),"") -> 10035380 | BS12: =BH12+BL12+BP12 -> #VALUE! | BT12: =SUM(BI12,BM12,BQ12) -> 0 | BU12: =SUM(BJ12,BN12,BR12) -> 19583186 | BV12: =IFERROR(VLOOKUP(M12,Basilee24,12,FALSE),"") | BW12: =BY12-BX12 -> #VALUE! | BX12: =IFERROR(VLOOKUP(M12,BASALIM,12,FALSE),"") | BY12: =IFERROR(VLOOKUP(M12,BASFC,12,FALSE),"") -> 9323823.7 | BZ12: =IFERROR(VLOOKUP(M12,Basilee24,13,FALSE),"") | CD12: =IFERROR(VLOOKUP(M12,Basilee24,14,FALSE),"")
A13: =VLOOKUP(M13,BASCART4,3,FALSE) -> 112014774 | B13: =IFERROR(VLOOKUP(M13,BASILECARTERA,2,FALSE),"") | C13: =IFERROR(VLOOKUP(B13,DES,2,FALSE),"") | D13: =IFERROR(VLOOKUP(B13,DES,3,FALSE),"") | E13: =IFERROR(VLOOKUP(B13,DES,4,FALSE),"") | F13: =IFERROR(VLOOKUP(M13,BASILECART2,2,FALSE),"") | G13: =IFERROR(VLOOKUP(F13,DES,2,FALSE),"") | H13: =IFERROR(VLOOKUP(F13,DES,3,FALSE),"") | I13: =IFERROR(VLOOKUP(F13,DES,4,FALSE),"") | J13: =VLOOKUP(M13,BASCART4,2,FALSE) -> 62 | K13: =IFERROR(VLOOKUP(J13,A458DC1025,2,FALSE),"") -> 0.1 | L13: =IFERROR(VLOOKUP(J13,A458DC1025,3,FALSE),"") -> 0.11 | M13: MARCHINI RAMIRO | N13: =IFERROR(VLOOKUP(M13,Basilee24,3,FALSE),"") | O13: =(N13*1.601)*1.05 -> #VALUE! | P13: =R13-Q13 -> #VALUE! | Q13: =IFERROR(VLOOKUP(M13,BASALIM,3,FALSE),"") | R13: =IFERROR(VLOOKUP(M13,BASFC,3,FALSE),"") | S13: =R13-O13 -> #VALUE! | T13: =R13/O13 -> #VALUE! | U13: =IFERROR(VLOOKUP(M13,Basilee24,4,FALSE),"") | V13: 3000000 | W13: =Y13-X13 -> #VALUE! | X13: =IFERROR(VLOOKUP(M13,BASALIM,4,FALSE),"") | Y13: =IFERROR(VLOOKUP(M13,BASFC,4,FALSE),"") | Z13: =Y13-V13 -> #VALUE! | AA13: =Y13/V13 -> #VALUE! | AB13: =IFERROR(VLOOKUP(M13,Basilee24,5,FALSE),"") | AC13: 3000000 | AD13: =AF13-AE13 -> #VALUE! | AE13: =IFERROR(VLOOKUP(M13,BASALIM,5,FALSE),"") | AF13: =IFERROR(VLOOKUP(M13,BASFC,5,FALSE),"") | AG13: =AF13-AC13 -> #VALUE! | AH13: =AF13/AC13 -> #VALUE! | AI13: =SUM(O13,V13,AC13) -> #VALUE! | AJ13: =IFERROR(VLOOKUP(M13,trim2024,2,FALSE),"0") -> 0 | AK13: =SUM(AE13,X13,Q13) -> 0 | AL13: =SUM(P13,W13,AD13) -> #VALUE! | AM13: =AF13+Y13+R13 -> #VALUE! | AN13: =AM13-AJ13 -> #VALUE! | AO13: =AM13/AJ13 -> #VALUE! | AP13: =IFERROR(VLOOKUP(M13,Basilee24,6,FALSE),"") | AQ13: =AS13-AR13 -> #VALUE! | AR13: =IFERROR(VLOOKUP(M13,BASALIM,6,FALSE),"") | AS13: =IFERROR(VLOOKUP(M13,BASFC,6,FALSE),"") | AT13: =IFERROR(VLOOKUP(M13,Basilee24,7,FALSE),"") | AU13: =AW13-AV13 -> #VALUE! | AV13: =IFERROR(VLOOKUP(M13,BASALIM,7,FALSE),"") | AW13: =IFERROR(VLOOKUP(M13,BASFC,7,FALSE),"") | AX13: =IFERROR(VLOOKUP(M13,Basilee24,8,FALSE),"") | AY13: =BA13-AZ13 -> #VALUE! | AZ13: =IFERROR(VLOOKUP(M13,BASALIM,8,FALSE),"") | BA13: =IFERROR(VLOOKUP(M13,BASFC,8,FALSE),"") | BB13: =BH13+AY13+AU13 -> #VALUE! | BC13: =BI13+AZ13+AV13 -> #VALUE! | BD13: =BJ13+BA13+AW13 -> #VALUE! | BE13: =BB13+AL13 -> #VALUE! | BF13: =BC13+AK13 -> #VALUE! | BG13: =SUM(BD13+AM13) -> #VALUE! | BH13: =BJ13-BI13 -> #VALUE! | BI13: =IFERROR(VLOOKUP(M13,BASALIM,9,FALSE),"") | BJ13: =IFERROR(VLOOKUP(M13,BASFC,9,FALSE),"") | BK13: =IFERROR(VLOOKUP(M13,Basilee24,10,FALSE),"") | BL13: =BN13-BM13 -> #VALUE! | BM13: =IFERROR(VLOOKUP(M13,BASALIM,10,FALSE),"") | BN13: =IFERROR(VLOOKUP(M13,BASFC,10,FALSE),"") | BO13: =IFERROR(VLOOKUP(M13,Basilee24,11,FALSE),"") | BP13: =BR13-BQ13 -> #VALUE! | BQ13: =IFERROR(VLOOKUP(M13,BASALIM,11,FALSE),"") | BR13: =IFERROR(VLOOKUP(M13,BASFC,11,FALSE),"") | BS13: =BH13+BL13+BP13 -> #VALUE! | BT13: =SUM(BI13,BM13,BQ13) -> 0 | BU13: =SUM(BJ13,BN13,BR13) -> 0 | BV13: =IFERROR(VLOOKUP(M13,Basilee24,12,FALSE),"") | BW13: =BY13-BX13 -> #VALUE! | BX13: =IFERROR(VLOOKUP(M13,BASALIM,12,FALSE),"") | BY13: =IFERROR(VLOOKUP(M13,BASFC,12,FALSE),"") | BZ13: =IFERROR(VLOOKUP(M13,Basilee24,13,FALSE),"") | CD13: =IFERROR(VLOOKUP(M13,Basilee24,14,FALSE),"")
A14: =VLOOKUP(M14,BASCART4,3,FALSE) -> 112014270 | B14: =IFERROR(VLOOKUP(M14,BASILECARTERA,2,FALSE),"") -> 10 | C14: =IFERROR(VLOOKUP(B14,DES,2,FALSE),"") -> 0.15 | D14: =IFERROR(VLOOKUP(B14,DES,3,FALSE),"") -> 0.23 | E14: =IFERROR(VLOOKUP(B14,DES,4,FALSE),"") -> 0 | F14: =IFERROR(VLOOKUP(M14,BASILECART2,2,FALSE),"") -> 31 | G14: =IFERROR(VLOOKUP(F14,DES,2,FALSE),"") -> 0.1 | H14: =IFERROR(VLOOKUP(F14,DES,3,FALSE),"") -> 0.23 | I14: =IFERROR(VLOOKUP(F14,DES,4,FALSE),"") -> 0 | J14: =VLOOKUP(M14,BASCART4,2,FALSE) -> 61 | K14: =IFERROR(VLOOKUP(J14,A458DC1025,2,FALSE),"") -> 0.1 | L14: =IFERROR(VLOOKUP(J14,A458DC1025,3,FALSE),"") -> 0.14 | M14: EL GRAN CHEF/MAZZANTI/UNSWORTH/ LALOTTA | N14: =IFERROR(VLOOKUP(M14,Basilee24,3,FALSE),"") -> 2301571.2 | O14: =(N14*1.601)*1.05 -> 3869056.3 | P14: =R14-Q14 -> 283617.12 | Q14: =IFERROR(VLOOKUP(M14,BASALIM,3,FALSE),"") -> 3255976.6 | R14: =IFERROR(VLOOKUP(M14,BASFC,3,FALSE),"") -> 3539593.7 | S14: =R14-O14 -> -329462.58 | T14: =R14/O14 -> 0.91484679 | U14: =IFERROR(VLOOKUP(M14,Basilee24,4,FALSE),"") -> 2242152.6 | V14: =U14*1.7245 -> 3866592.2 | W14: =Y14-X14 -> 3647981.9 | X14: =IFERROR(VLOOKUP(M14,BASALIM,4,FALSE),"") -> 4924669.1 | Y14: =IFERROR(VLOOKUP(M14,BASFC,4,FALSE),"") -> 8572651.1 | Z14: =Y14-V14 -> 4706058.9 | AA14: =Y14/V14 -> 2.2171076 | AB14: =IFERROR(VLOOKUP(M14,Basilee24,5,FALSE),"") -> 2042682.8 | AC14: =(AB14*1.5955)*1.03 -> 3356873.4 | AD14: =AF14-AE14 -> 0 | AE14: =IFERROR(VLOOKUP(M14,BASALIM,5,FALSE),"") -> 3345432 | AF14: =IFERROR(VLOOKUP(M14,BASFC,5,FALSE),"") -> 3345432 | AG14: =AF14-AC14 -> -11441.384 | AH14: =AF14/AC14 -> 0.99659165 | AI14: =SUM(O14,V14,AC14) -> 11092522 | AJ14: =IFERROR(VLOOKUP(M14,trim2024,2,FALSE),"0") -> 6455394.8 | AK14: =SUM(AE14,X14,Q14) -> 11526078 | AL14: =SUM(P14,W14,AD14) -> 3931599.1 | AM14: =AF14+Y14+R14 -> 15457677 | AN14: =AM14-AJ14 -> 9002281.9 | AO14: =AM14/AJ14 -> 2.3945362 | AP14: =IFERROR(VLOOKUP(M14,Basilee24,6,FALSE),"") -> 1429559.7 | AQ14: =AS14-AR14 -> 660116.6 | AR14: =IFERROR(VLOOKUP(M14,BASALIM,6,FALSE),"") -> 2819252.4 | AS14: =IFERROR(VLOOKUP(M14,BASFC,6,FALSE),"") -> 3479369 | AT14: =IFERROR(VLOOKUP(M14,Basilee24,7,FALSE),"") -> 2040779.7 | AU14: =AW14-AV14 -> 0 | AV14: =IFERROR(VLOOKUP(M14,BASALIM,7,FALSE),"") -> 3715085.5 | AW14: =IFERROR(VLOOKUP(M14,BASFC,7,FALSE),"") -> 3715085.5 | AX14: =IFERROR(VLOOKUP(M14,Basilee24,8,FALSE),"") -> 1216559.3 | AY14: =BA14-AZ14 -> 241728.27 | AZ14: =IFERROR(VLOOKUP(M14,BASALIM,8,FALSE),"") -> 1793149.1 | BA14: =IFERROR(VLOOKUP(M14,BASFC,8,FALSE),"") -> 2034877.4 | BB14: =BH14+AY14+AU14 -> 241728.27 | BC14: =BI14+AZ14+AV14 -> 12554787 | BD14: =BJ14+BA14+AW14 -> 12796516 | BE14: =BB14+AL14 -> 4173327.3 | BF14: =BC14+AK14 -> 24080865 | BG14: =SUM(BD14+AM14) -> 28254192 | BH14: =BJ14-BI14 -> 0 | BI14: =IFERROR(VLOOKUP(M14,BASALIM,9,FALSE),"") -> 7046552.7 | BJ14: =IFERROR(VLOOKUP(M14,BASFC,9,FALSE),"") -> 7046552.7 | BK14: =IFERROR(VLOOKUP(M14,Basilee24,10,FALSE),"") -> 4471137.7 | BL14: =BN14-BM14 -> 0 | BM14: =IFERROR(VLOOKUP(M14,BASALIM,10,FALSE),"") -> 5536190.1 | BN14: =IFERROR(VLOOKUP(M14,BASFC,10,FALSE),"") -> 5536190.1 | BO14: =IFERROR(VLOOKUP(M14,Basilee24,11,FALSE),"") -> 1436000.4 | BP14: =BR14-BQ14 -> 0 | BQ14: =IFERROR(VLOOKUP(M14,BASALIM,11,FALSE),"") -> 3549071.8 | BR14: =IFERROR(VLOOKUP(M14,BASFC,11,FALSE),"") -> 3549071.8 | BS14: =BH14+BL14+BP14 -> 0 | BT14: =SUM(BI14,BM14,BQ14) -> 16131815 | BU14: =SUM(BJ14,BN14,BR14) -> 16131815 | BV14: =IFERROR(VLOOKUP(M14,Basilee24,12,FALSE),"") -> 2198564.3 | BW14: =BY14-BX14 -> 7559.92 | BX14: =IFERROR(VLOOKUP(M14,BASALIM,12,FALSE),"") -> 4187832.4 | BY14: =IFERROR(VLOOKUP(M14,BASFC,12,FALSE),"") -> 4195392.3 | BZ14: =IFERROR(VLOOKUP(M14,Basilee24,13,FALSE),"") -> 1800247.2 | CD14: =IFERROR(VLOOKUP(M14,Basilee24,14,FALSE),"") -> 2456583.4
A15: =VLOOKUP(M15,BASCART4,3,FALSE) -> 112014628 | B15: =IFERROR(VLOOKUP(M15,BASILECARTERA,2,FALSE),"") -> 31 | C15: =IFERROR(VLOOKUP(B15,DES,2,FALSE),"") -> 0.1 | D15: =IFERROR(VLOOKUP(B15,DES,3,FALSE),"") -> 0.23 | E15: =IFERROR(VLOOKUP(B15,DES,4,FALSE),"") -> 0 | F15: =IFERROR(VLOOKUP(M15,BASILECART2,2,FALSE),"") -> 31 | G15: =IFERROR(VLOOKUP(F15,DES,2,FALSE),"") -> 0.1 | H15: =IFERROR(VLOOKUP(F15,DES,3,FALSE),"") -> 0.23 | I15: =IFERROR(VLOOKUP(F15,DES,4,FALSE),"") -> 0 | J15: =VLOOKUP(M15,BASCART4,2,FALSE) -> 61 | K15: =IFERROR(VLOOKUP(J15,A458DC1025,2,FALSE),"") -> 0.1 | L15: =IFERROR(VLOOKUP(J15,A458DC1025,3,FALSE),"") -> 0.14 | M15: FLORENCIA BEHRENS/EMILIANO QUINTEROS | N15: =IFERROR(VLOOKUP(M15,Basilee24,3,FALSE),"") | P15: =R15-Q15 -> #VALUE! | Q15: =IFERROR(VLOOKUP(M15,BASALIM,3,FALSE),"") | R15: =IFERROR(VLOOKUP(M15,BASFC,3,FALSE),"") -> 404473.08 | S15: =R15-O15 -> 404473.08 | T15: =R15/O15 -> #DIV/0! | U15: =IFERROR(VLOOKUP(M15,Basilee24,4,FALSE),"") | W15: =Y15-X15 -> #VALUE! | X15: =IFERROR(VLOOKUP(M15,BASALIM,4,FALSE),"") | Y15: =IFERROR(VLOOKUP(M15,BASFC,4,FALSE),"") -> 2078461.9 | Z15: =Y15-V15 -> 2078461.9 | AA15: =IFERROR(Y15/V15,"") | AB15: =IFERROR(VLOOKUP(M15,Basilee24,5,FALSE),"") | AC15: 600000 | AD15: =AF15-AE15 -> #VALUE! | AE15: =IFERROR(VLOOKUP(M15,BASALIM,5,FALSE),"") | AF15: =IFERROR(VLOOKUP(M15,BASFC,5,FALSE),"") -> 2424631.2 | AG15: =AF15-AC15 -> 1824631.2 | AH15: =IFERROR(AF15/AC15,"") -> 4.041052 | AI15: =SUM(O15,V15,AC15) -> 600000 | AJ15: =IFERROR(VLOOKUP(M15,trim2024,2,FALSE),"0") -> 2473307.5 | AK15: =SUM(AE15,X15,Q15) -> 0 | AL15: =SUM(P15,W15,AD15) -> #VALUE! | AM15: =AF15+Y15+R15 -> 4907566.2 | AN15: =AM15-AJ15 -> 2434258.6 | AO15: =AM15/AJ15 -> 1.9842119 | AP15: =IFERROR(VLOOKUP(M15,Basilee24,6,FALSE),"") | AQ15: =AS15-AR15 -> #VALUE! | AR15: =IFERROR(VLOOKUP(M15,BASALIM,6,FALSE),"") | AS15: =IFERROR(VLOOKUP(M15,BASFC,6,FALSE),"") -> 1790094.5 | AT15: =IFERROR(VLOOKUP(M15,Basilee24,7,FALSE),"") | AU15: =AW15-AV15 -> #VALUE! | AV15: =IFERROR(VLOOKUP(M15,BASALIM,7,FALSE),"") | AW15: =IFERROR(VLOOKUP(M15,BASFC,7,FALSE),"") -> 1561155.2 | AX15: =IFERROR(VLOOKUP(M15,Basilee24,8,FALSE),"") | AY15: =BA15-AZ15 -> #VALUE! | AZ15: =IFERROR(VLOOKUP(M15,BASALIM,8,FALSE),"") | BA15: =IFERROR(VLOOKUP(M15,BASFC,8,FALSE),"") -> 1219328.2 | BB15: =BH15+AY15+AU15 -> #VALUE! | BC15: =BI15+AZ15+AV15 -> #VALUE! | BD15: =BJ15+BA15+AW15 -> 3500929 | BE15: =BB15+AL15 -> #VALUE! | BF15: =BC15+AK15 -> #VALUE! | BG15: =SUM(BD15+AM15) -> 8408495.2 | BH15: =BJ15-BI15 -> #VALUE! | BI15: =IFERROR(VLOOKUP(M15,BASALIM,9,FALSE),"") | BJ15: =IFERROR(VLOOKUP(M15,BASFC,9,FALSE),"") -> 720445.51 | BK15: =IFERROR(VLOOKUP(M15,Basilee24,10,FALSE),"") | BL15: =BN15-BM15 -> #VALUE! | BM15: =IFERROR(VLOOKUP(M15,BASALIM,10,FALSE),"") | BN15: =IFERROR(VLOOKUP(M15,BASFC,10,FALSE),"") -> 631748.06 | BO15: =IFERROR(VLOOKUP(M15,Basilee24,11,FALSE),"") | BP15: =BR15-BQ15 -> #VALUE! | BQ15: =IFERROR(VLOOKUP(M15,BASALIM,11,FALSE),"") | BR15: =IFERROR(VLOOKUP(M15,BASFC,11,FALSE),"") -> 2903013.3 | BS15: =BH15+BL15+BP15 -> #VALUE! | BT15: =SUM(BI15,BM15,BQ15) -> 0 | BU15: =SUM(BJ15,BN15,BR15) -> 4255206.8 | BV15: =IFERROR(VLOOKUP(M15,Basilee24,12,FALSE),"") | BW15: =BY15-BX15 -> #VALUE! | BX15: =IFERROR(VLOOKUP(M15,BASALIM,12,FALSE),"") | BY15: =IFERROR(VLOOKUP(M15,BASFC,12,FALSE),"") -> 5264118.7 | BZ15: =IFERROR(VLOOKUP(M15,Basilee24,13,FALSE),"") | CD15: =IFERROR(VLOOKUP(M15,Basilee24,14,FALSE),"") | CI15: ENERO, FEBRERO, MARZO CERRADO
